Workbook

Sheet Summary
A1: HSR vs Central Hub vs Combined vs BLR City — Executive Summary
A2: Updated through 16-Jul. Combined = task-volume-weighted pooling of HSR + Central. BLR City = city-wide aggregate across all hubs (no per-day task count available, so uses an SD-based control limit rather than the binomial p-chart formula).
A4: View | B4: Metric | C4: Target | D4: Avg. Performance | E4: Current Center (p-bar) | F4: Days Meeting Target | G4: CUSUM Shifts Detected
A5: HSR | B5: Arrival OT % | C5: ='HSR Arrival OT'!S5 -> 0.95 | D5: ='HSR Arrival OT'!S9 -> 0.90215234 | E5: ='HSR Arrival OT'!S11 -> 0.91994262 | F5: ='HSR Arrival OT'!S8 -> 8/34 | G5: ='HSR Arrival OT'!S7 -> 3
A6: HSR | B6: Availability % | C6: ='HSR Availability'!S5 -> 0.9 | D6: ='HSR Availability'!S9 -> 0.77230588 | E6: ='HSR Availability'!S11 -> 0.76305 | F6: ='HSR Availability'!S8 -> 10/34 | G6: ='HSR Availability'!S7 -> 5
A7: Central Hub | B7: Arrival OT % | C7: ='Central Arrival OT'!S5 -> 0.95 | D7: ='Central Arrival OT'!S9 -> 0.8330998 | E7: ='Central Arrival OT'!S11 -> 0.79893934 | F7: ='Central Arrival OT'!S8 -> 5/29 | G7: ='Central Arrival OT'!S7 -> 3
A8: Central Hub | B8: Availability % | C8: ='Central Availability'!S5 -> 0.9 | D8: ='Central Availability'!S9 -> 0.59921034 | E8: ='Central Availability'!S11 -> 0.45533333 | F8: ='Central Availability'!S8 -> 5/29 | G8: ='Central Availability'!S7 -> 3
A9: Combined | B9: Arrival OT % | C9: ='Combined Arrival OT'!S5 -> 0.95 | D9: ='Combined Arrival OT'!S9 -> 0.88543674 | E9: ='Combined Arrival OT'!S11 -> 0.89810153 | F9: ='Combined Arrival OT'!S8 -> 3/34 | G9: ='Combined Arrival OT'!S7 -> 3
A10: Combined | B10: Availability % | C10: ='Combined Availability'!S5 -> 0.9 | D10: ='Combined Availability'!S9 -> 0.72929046 | E10: ='Combined Availability'!S11 -> 0.70232343 | F10: ='Combined Availability'!S8 -> 4/34 | G10: ='Combined Availability'!S7 -> 5
A11: BLR City | B11: Arrival OT % (all hubs) | C11: ='BLR City Arrival OT'!S5 -> 0.95 | D11: ='BLR City Arrival OT'!S9 -> 0.94824118 | E11: ='BLR City Arrival OT'!S11 -> 0.94415 | F11: ='BLR City Arrival OT'!S8 -> 16/34 | G11: ='BLR City Arrival OT'!S7 -> 3
A13: Key takeaway
A14: BLR City overall (94.8% avg, right at the 95% target) performs far better than HSR (90.2%) or Central Hub (83.3%) individually — meaning the rest of the city's hubs are pulling the city average up while HSR and especially Central Hub lag behind. Central Hub remains the weakest link on both metrics, most severely on Availability (avg 59.9% vs 90% target, current CUSUM center 45.5% — a ~45-point gap). The Combined (HSR+Central pooled) view sits well below the City average, confirming these two hubs are underperforming relative to the rest of BLR, not just relative to target. Central Hub should remain the top investigation priority, and it's worth understanding what the better-performing city hubs are doing differently.

Sheet Raw-Data
A1: Combined | I1: HSR Hub | N1: Central Hub
A2: Date | B2: Combined n (HSR+Central) | C2: Combined OT % | D2: Combined Availability % | E2: HSR n | F2: Central n | G2: BLR City Total Arrival | I2: Date | J2: # Total Tasks | K2: Overall OT % | L2: Availability % | N2: Date | O2: # Total Tasks | P2: Overall OT % | Q2: Availability
G3: 0.9488 | I3: 46222 | J3: 136 | K3: 0.9412 | L3: 0.912 | N3: 46222 | O3: 63 | P3: 0.836 | Q3: 0.6081
G4: 0.9579 | I4: 46221 | J4: 143 | K4: 0.928 | L4: 0.6593 | N4: 46221 | O4: 58 | P4: 0.898 | Q4: 0.6959
G5: 0.9486 | I5: 46220 | J5: 119 | K5: 0.9896 | L5: 0.8024 | N5: 46220 | O5: 49 | P5: 1 | Q5: 0.686
A6: =I6 -> 46219 | B6: =J6+IF(O6="",0,O6) -> 190 | C6: =(J6*K6+IF(O6="",0,O6*P6))/B6 -> 0.86999895 | D6: =(J6*L6+IF(O6="",0,O6*Q6))/B6 -> 0.67565579 | E6: 136 | F6: =IF(O6="",0,O6) -> 54 | G6: 0.9485 | I6: 46219 | J6: 136 | K6: 0.9292 | L6: 0.697 | N6: 46219 | O6: 54 | P6: 0.7209 | Q6: 0.6219
A7: =I7 -> 46218 | B7: =J7+IF(O7="",0,O7) -> 181 | C7: =(J7*K7+IF(O7="",0,O7*P7))/B7 -> 0.8518768 | D7: =(J7*L7+IF(O7="",0,O7*Q7))/B7 -> 0.86706188 | E7: =J7 -> 115 | F7: =IF(O7="",0,O7) -> 66 | G7: 0.9434 | I7: 46218 | J7: 115 | K7: 0.9263 | L7: 0.9502 | N7: 46218 | O7: 66 | P7: 0.7222 | Q7: 0.7222
A8: =I8 -> 46217 | B8: =J8+IF(O8="",0,O8) -> 194 | C8: =(J8*K8+IF(O8="",0,O8*P8))/B8 -> 0.9124863 | D8: =(J8*L8+IF(O8="",0,O8*Q8))/B8 -> 0.83635052 | E8: =J8 -> 140 | F8: =IF(O8="",0,O8) -> 54 | G8: 0.9482 | I8: 46217 | J8: 140 | K8: 0.95762712 | L8: 0.99 | N8: 46217 | O8: 54 | P8: 0.79545455 | Q8: 0.438
A9: =I9 -> 46216 | B9: =J9+IF(O9="",0,O9) -> 191 | C9: =(J9*K9+IF(O9="",0,O9*P9))/B9 -> 0.90184071 | D9: =(J9*L9+IF(O9="",0,O9*Q9))/B9 -> 0.61926702 | E9: =J9 -> 131 | F9: =IF(O9="",0,O9) -> 60 | G9: 0.9511 | I9: 46216 | J9: 131 | K9: 0.90178571 | L9: 0.58 | N9: 46216 | O9: 60 | P9: 0.90196078 | Q9: 0.705
A10: =I10 -> 46215 | B10: =J10+IF(O10="",0,O10) -> 182 | C10: =(J10*K10+IF(O10="",0,O10*P10))/B10 -> 0.9120707 | D10: =(J10*L10+IF(O10="",0,O10*Q10))/B10 -> 0.73088297 | E10: =J10 -> 137 | F10: =IF(O10="",0,O10) -> 45 | G10: 0.9581 | I10: 46215 | J10: 137 | K10: 0.96330275 | L10: 0.8261 | N10: 46215 | O10: 45 | P10: 0.75609756 | Q10: 0.441
A11: =I11 -> 46214 | B11: =J11+IF(O11="",0,O11) -> 184 | C11: =(J11*K11+IF(O11="",0,O11*P11))/B11 -> 0.95855343 | D11: =(J11*L11+IF(O11="",0,O11*Q11))/B11 -> 0.96843478 | E11: =J11 -> 136 | F11: =IF(O11="",0,O11) -> 48 | G11: 0.9553 | I11: 46214 | J11: 136 | K11: 0.94392523 | L11: 1 | N11: 46214 | O11: 48 | P11: 1 | Q11: 0.879
A12: =I12 -> 46213 | B12: =J12+IF(O12="",0,O12) -> 179 | C12: =(J12*K12+IF(O12="",0,O12*P12))/B12 -> 0.93952545 | D12: =(J12*L12+IF(O12="",0,O12*Q12))/B12 -> 0.93012737 | E12: =J12 -> 137 | F12: =IF(O12="",0,O12) -> 42 | G12: 0.9522 | I12: 46213 | J12: 137 | K12: 0.95412844 | L12: 0.9924 | N12: 46213 | O12: 42 | P12: 0.89189189 | Q12: 0.727
A13: =I13 -> 46212 | B13: =J13+IF(O13="",0,O13) -> 143 | C13: =(J13*K13+IF(O13="",0,O13*P13))/B13 -> 0.96840627 | D13: =(J13*L13+IF(O13="",0,O13*Q13))/B13 -> 0.83901748 | E13: =J13 -> 105 | F13: =IF(O13="",0,O13) -> 38 | G13: 0.9505 | I13: 46212 | J13: 105 | K13: 0.97826087 | L13: 0.9447 | N13: 46212 | O13: 38 | P13: 0.94117647 | Q13: 0.547
A14: =I14 -> 46211 | B14: =J14+IF(O14="",0,O14) -> 160 | C14: =(J14*K14+IF(O14="",0,O14*P14))/B14 -> 0.8478343 | D14: =(J14*L14+IF(O14="",0,O14*Q14))/B14 -> 0.79858 | E14: =J14 -> 108 | F14: =IF(O14="",0,O14) -> 52 | G14: 0.9584 | I14: 46211 | J14: 108 | K14: 0.90697674 | L14: 0.8316 | N14: 46211 | O14: 52 | P14: 0.725 | Q14: 0.73
A15: =I15 -> 46210 | B15: =J15+IF(O15="",0,O15) -> 156 | C15: =(J15*K15+IF(O15="",0,O15*P15))/B15 -> 0.87143801 | D15: =(J15*L15+IF(O15="",0,O15*Q15))/B15 -> 0.73415705 | E15: =J15 -> 115 | F15: =IF(O15="",0,O15) -> 41 | G15: 0.9389 | I15: 46210 | J15: 115 | K15: 0.89690722 | L15: 0.8811 | N15: 46210 | O15: 41 | P15: 0.8 | Q15: 0.322
A16: =I16 -> 46209 | B16: =J16+IF(O16="",0,O16) -> 142 | C16: =(J16*K16+IF(O16="",0,O16*P16))/B16 -> 0.89072152 | D16: =(J16*L16+IF(O16="",0,O16*Q16))/B16 -> 0.72235634 | E16: =J16 -> 94 | F16: =IF(O16="",0,O16) -> 48 | G16: 0.938 | I16: 46209 | J16: 94 | K16: 0.93421053 | L16: 0.9799 | N16: 46209 | O16: 48 | P16: 0.80555556 | Q16: 0.218
A17: =I17 -> 46208 | B17: =J17+IF(O17="",0,O17) -> 197 | C17: =(J17*K17+IF(O17="",0,O17*P17))/B17 -> 0.88493205 | D17: =(J17*L17+IF(O17="",0,O17*Q17))/B17 -> 0.51434518 | E17: =J17 -> 140 | F17: =IF(O17="",0,O17) -> 57 | G17: 0.9518 | I17: 46208 | J17: 140 | K17: 0.90322581 | L17: 0.5837 | N17: 46208 | O17: 57 | P17: 0.84 | Q17: 0.344
A18: =I18 -> 46207 | B18: =J18+IF(O18="",0,O18) -> 183 | C18: =(J18*K18+IF(O18="",0,O18*P18))/B18 -> 0.87922084 | D18: =(J18*L18+IF(O18="",0,O18*Q18))/B18 -> 0.5431377 | E18: =J18 -> 129 | F18: =IF(O18="",0,O18) -> 54 | G18: 0.952 | I18: 46207 | J18: 129 | K18: 0.90654206 | L18: 0.5658 | N18: 46207 | O18: 54 | P18: 0.81395349 | Q18: 0.489
... A34: =I34 -> 46191 | B34: =J34+IF(O34="",0,O34) -> 139 | C34: =(J34*K34+IF(O34="",0,O34*P34))/B34 -> 0.92826915 | D34: =(J34*L34+IF(O34="",0,O34*Q34))/B34 -> 0.69176259 | E34: =J34 -> 95 | F34: =IF(O34="",0,O34) -> 44 | G34: 0.956 | I34: 46191 | J34: 95 | K34: 0.95294118 | L34: 0.549 | N34: 46191 | O34: 44 | P34: 0.875 | Q34: 1
A35: =I35 -> 46190 | B35: =J35+IF(O35="",0,O35) -> 104 | C35: =(J35*K35+IF(O35="",0,O35*P35))/B35 -> 0.87951807 | D35: =(J35*L35+IF(O35="",0,O35*Q35))/B35 -> 0.5584 | E35: =J35 -> 104 | F35: =IF(O35="",0,O35) -> 0 | G35: 0.9446 | I35: 46190 | J35: 104 | K35: 0.87951807 | L35: 0.5584
A36: =I36 -> 46189 | B36: =J36+IF(O36="",0,O36) -> 114 | C36: =(J36*K36+IF(O36="",0,O36*P36))/B36 -> 0.93548387 | D36: =(J36*L36+IF(O36="",0,O36*Q36))/B36 -> 0.8852 | E36: =J36 -> 114 | F36: =IF(O36="",0,O36) -> 0 | G36: 0.9419 | I36: 46189 | J36: 114 | K36: 0.93548387 | L36: 0.8852
A37: =I37 -> 46188 | B37: =J37+IF(O37="",0,O37) -> 101 | C37: =(J37*K37+IF(O37="",0,O37*P37))/B37 -> 0.90804598 | D37: =(J37*L37+IF(O37="",0,O37*Q37))/B37 -> 0.44 | E37: =J37 -> 101 | F37: =IF(O37="",0,O37) -> 0 | G37: 0.9464 | I37: 46188 | J37: 101 | K37: 0.90804598 | L37: 0.44
A38: =I38 -> 46187 | B38: =J38+IF(O38="",0,O38) -> 112 | C38: =(J38*K38+IF(O38="",0,O38*P38))/B38 -> 0.9375 | D38: =(J38*L38+IF(O38="",0,O38*Q38))/B38 -> 0.9783 | E38: =J38 -> 112 | F38: =IF(O38="",0,O38) -> 0 | G38: 0.9451 | I38: 46187 | J38: 112 | K38: 0.9375 | L38: 0.9783
A39: =I39 -> 46186 | B39: =J39+IF(O39="",0,O39) -> 125 | C39: =(J39*K39+IF(O39="",0,O39*P39))/B39 -> 0.93939394 | D39: =(J39*L39+IF(O39="",0,O39*Q39))/B39 -> 0.8824 | E39: =J39 -> 125 | F39: =IF(O39="",0,O39) -> 0 | G39: 0.949 | I39: 46186 | J39: 125 | K39: 0.93939394 | L39: 0.8824

Sheet HSR Arrival OT
A1: HSR — Arrival On-Time % — CUSUM Control Chart & Target Analysis
A2: Tabular CUSUM: center line (p-bar) re-estimates once a sustained shift is detected (no UCL). k=0.5 SD allowance, H=4 SD decision interval. S(H)/S(L) floored at zero. Data pulls live from 'Raw-Data' — extend formulas down after adding new rows there.
A4: Date | B4: Sample Size (n) | C4: Arrival OT % | D4: p-bar (CL) | E4: SD | F4: LCL | G4: Target | H4: Z value | I4: S(H) | J4: S(L) | K4: Shift detected? | L4: Count | M4: Consider in calc | N4: Rows | O4: Meets Target? | P4: Ignore? | R4: Summary statistics
A5: ='Raw-Data'!I39 -> 46186 | B5: ='Raw-Data'!J39 -> 125 | C5: ='Raw-Data'!K39 -> 0.93939394 | D5: 0.9 | E5: 0.05 | F5: =MAX(0,D5-3*SQRT(D5*(1-D5)/B5)) -> 0.81950155 | G5: 0.95 | H5: =(C5-D5)/E5 -> 0.78787879 | I5: 0 | J5: 0 | K5: {=IFERROR(OR(ABS(I5)>=4, ABS(J5)>=4),FALSE())} -> FALSE | L5: 0 | M5: =IF(P5="y","",C5) -> 0.93939394 | N5: 1 | O5: =IF(C5>=G5,"Yes","No") -> No | R5: Target | S5: 0.95
A6: ='Raw-Data'!I38 -> 46187 | B6: ='Raw-Data'!J38 -> 112 | C6: ='Raw-Data'!K38 -> 0.9375 | D6: =IF(NOT($K5),D5,AVERAGE(OFFSET($M5,-1*MAX($L5,N5),0):OFFSET($M5,0,0))) -> 0.9 | E6: =IF(NOT($K5),E5,IFERROR(STDEV(OFFSET($M5,-1*MAX($L5,N5),0):OFFSET($M5,0,0)),E5)) -> 0.05 | F6: =MAX(0,D6-3*SQRT(D6*(1-D6)/B6)) -> 0.81495799 | G6: 0.95 | H6: =(C6-D6)/E6 -> 0.75 | I6: =IF(P6="y",I5,IF(K5,0,MAX(0,I5+H6-0.5))) -> 0.25 | J6: =IF(P6="y",J5,IF(K5,0,MAX(0,J5-H6+0.5))) -> 0 | K6: {=IFERROR(OR(ABS(I6)>=4, ABS(J6)>=4),FALSE())} -> FALSE | L6: =IF(K5,0,L5+1) -> 1 | M6: =IF(P6="y","",C6) -> 0.9375 | N6: =MIN(5,N5+1) -> 2 | O6: =IF(C6>=G6,"Yes","No") -> No | R6: Number of days (k) | S6: 34
A7: ='Raw-Data'!I37 -> 46188 | B7: ='Raw-Data'!J37 -> 101 | C7: ='Raw-Data'!K37 -> 0.90804598 | D7: =IF(NOT($K6),D6,AVERAGE(OFFSET($M6,-1*MAX($L6,N6),0):OFFSET($M6,0,0))) -> 0.9 | E7: =IF(NOT($K6),E6,IFERROR(STDEV(OFFSET($M6,-1*MAX($L6,N6),0):OFFSET($M6,0,0)),E6)) -> 0.05 | F7: =MAX(0,D7-3*SQRT(D7*(1-D7)/B7)) -> 0.81044665 | G7: 0.95 | H7: =(C7-D7)/E7 -> 0.16091954 | I7: =IF(P7="y",I6,IF(K6,0,MAX(0,I6+H7-0.5))) -> 0 | J7: =IF(P7="y",J6,IF(K6,0,MAX(0,J6-H7+0.5))) -> 0.33908046 | K7: {=IFERROR(OR(ABS(I7)>=4, ABS(J7)>=4),FALSE())} -> FALSE | L7: =IF(K6,0,L6+1) -> 2 | M7: =IF(P7="y","",C7) -> 0.90804598 | N7: =MIN(5,N6+1) -> 3 | O7: =IF(C7>=G7,"Yes","No") -> No | R7: Shifts detected (CUSUM) | S7: =COUNTIF(K5:K38,TRUE()) -> 3
A8: ='Raw-Data'!I36 -> 46189 | B8: ='Raw-Data'!J36 -> 114 | C8: ='Raw-Data'!K36 -> 0.93548387 | D8: =IF(NOT($K7),D7,AVERAGE(OFFSET($M7,-1*MAX($L7,N7),0):OFFSET($M7,0,0))) -> 0.9 | E8: =IF(NOT($K7),E7,IFERROR(STDEV(OFFSET($M7,-1*MAX($L7,N7),0):OFFSET($M7,0,0)),E7)) -> 0.05 | F8: =MAX(0,D8-3*SQRT(D8*(1-D8)/B8)) -> 0.81570728 | G8: 0.95 | H8: =(C8-D8)/E8 -> 0.70967742 | I8: =IF(P8="y",I7,IF(K7,0,MAX(0,I7+H8-0.5))) -> 0.20967742 | J8: =IF(P8="y",J7,IF(K7,0,MAX(0,J7-H8+0.5))) -> 0.12940304 | K8: {=IFERROR(OR(ABS(I8)>=4, ABS(J8)>=4),FALSE())} -> FALSE | L8: =IF(K7,0,L7+1) -> 3 | M8: =IF(P8="y","",C8) -> 0.93548387 | N8: =MIN(5,N7+1) -> 4 | O8: =IF(C8>=G8,"Yes","No") -> No | R8: Days meeting target | S8: =COUNTIF(O5:O38,"Yes")&"/"&34 -> 8/34
A9: ='Raw-Data'!I35 -> 46190 | B9: ='Raw-Data'!J35 -> 104 | C9: ='Raw-Data'!K35 -> 0.87951807 | D9: =IF(NOT($K8),D8,AVERAGE(OFFSET($M8,-1*MAX($L8,N8),0):OFFSET($M8,0,0))) -> 0.9 | E9: =IF(NOT($K8),E8,IFERROR(STDEV(OFFSET($M8,-1*MAX($L8,N8),0):OFFSET($M8,0,0)),E8)) -> 0.05 | F9: =MAX(0,D9-3*SQRT(D9*(1-D9)/B9)) -> 0.81174774 | G9: 0.95 | H9: =(C9-D9)/E9 -> -0.40963855 | I9: =IF(P9="y",I8,IF(K8,0,MAX(0,I8+H9-0.5))) -> 0 | J9: =IF(P9="y",J8,IF(K8,0,MAX(0,J8-H9+0.5))) -> 1.0390416 | K9: {=IFERROR(OR(ABS(I9)>=4, ABS(J9)>=4),FALSE())} -> FALSE | L9: =IF(K8,0,L8+1) -> 4 | M9: =IF(P9="y","",C9) -> 0.87951807 | N9: =MIN(5,N8+1) -> 5 | O9: =IF(C9>=G9,"Yes","No") -> No | R9: Average performance | S9: =AVERAGE(C5:C38) -> 0.90215234
A10: ='Raw-Data'!I34 -> 46191 | B10: ='Raw-Data'!J34 -> 95 | C10: ='Raw-Data'!K34 -> 0.95294118 | D10: =IF(NOT($K9),D9,AVERAGE(OFFSET($M9,-1*MAX($L9,N9),0):OFFSET($M9,0,0))) -> 0.9 | E10: =IF(NOT($K9),E9,IFERROR(STDEV(OFFSET($M9,-1*MAX($L9,N9),0):OFFSET($M9,0,0)),E9)) -> 0.05 | F10: =MAX(0,D10-3*SQRT(D10*(1-D10)/B10)) -> 0.80766195 | G10: 0.95 | H10: =(C10-D10)/E10 -> 1.0588235 | I10: =IF(P10="y",I9,IF(K9,0,MAX(0,I9+H10-0.5))) -> 0.55882353 | J10: =IF(P10="y",J9,IF(K9,0,MAX(0,J9-H10+0.5))) -> 0.48021807 | K10: {=IFERROR(OR(ABS(I10)>=4, ABS(J10)>=4),FALSE())} -> FALSE | L10: =IF(K9,0,L9+1) -> 5 | M10: =IF(P10="y","",C10) -> 0.95294118 | N10: =MIN(5,N9+1) -> 5 | O10: =IF(C10>=G10,"Yes","No") -> Yes | R10: Average gap to target | S10: =AVERAGE(C5:C38)-G5 -> -0.047847655
A11: ='Raw-Data'!I33 -> 46192 | B11: ='Raw-Data'!J33 -> 107 | C11: ='Raw-Data'!K33 -> 0.87234043 | D11: =IF(NOT($K10),D10,AVERAGE(OFFSET($M10,-1*MAX($L10,N10),0):OFFSET($M10,0,0))) -> 0.9 | E11: =IF(NOT($K10),E10,IFERROR(STDEV(OFFSET($M10,-1*MAX($L10,N10),0):OFFSET($M10,0,0)),E10)) -> 0.05 | F11: =MAX(0,D11-3*SQRT(D11*(1-D11)/B11)) -> 0.81299372 | G11: 0.95 | H11: =(C11-D11)/E11 -> -0.55319149 | I11: =IF(P11="y",I10,IF(K10,0,MAX(0,I10+H11-0.5))) -> 0 | J11: =IF(P11="y",J10,IF(K10,0,MAX(0,J10-H11+0.5))) -> 1.5334096 | K11: {=IFERROR(OR(ABS(I11)>=4, ABS(J11)>=4),FALSE())} -> FALSE | L11: =IF(K10,0,L10+1) -> 6 | M11: =IF(P11="y","",C11) -> 0.87234043 | N11: =MIN(5,N10+1) -> 5 | O11: =IF(C11>=G11,"Yes","No") -> No | R11: Current phase center (p-bar) | S11: =D38 -> 0.91994262
A12: ='Raw-Data'!I32 -> 46193 | B12: ='Raw-Data'!J32 -> 130 | C12: ='Raw-Data'!K32 -> 0.62280702 | D12: =IF(NOT($K11),D11,AVERAGE(OFFSET($M11,-1*MAX($L11,N11),0):OFFSET($M11,0,0))) -> 0.9 | E12: =IF(NOT($K11),E11,IFERROR(STDEV(OFFSET($M11,-1*MAX($L11,N11),0):OFFSET($M11,0,0)),E11)) -> 0.05 | F12: =MAX(0,D12-3*SQRT(D12*(1-D12)/B12)) -> 0.82106478 | G12: 0.95 | H12: =(C12-D12)/E12 -> -5.5438596 | I12: =IF(P12="y",I11,IF(K11,0,MAX(0,I11+H12-0.5))) -> 0 | J12: =IF(P12="y",J11,IF(K11,0,MAX(0,J11-H12+0.5))) -> 7.5772692 | K12: {=IFERROR(OR(ABS(I12)>=4, ABS(J12)>=4),FALSE())} -> TRUE | L12: =IF(K11,0,L11+1) -> 7 | M12: =IF(P12="y","",C12) -> 0.62280702 | N12: =MIN(5,N11+1) -> 5 | O12: =IF(C12>=G12,"Yes","No") -> No | R12: Current phase LCL | S12: =F38 -> 0.85013017
A13: ='Raw-Data'!I31 -> 46194 | B13: ='Raw-Data'!J31 -> 133 | C13: ='Raw-Data'!K31 -> 0.84745763 | D13: =IF(NOT($K12),D12,AVERAGE(OFFSET($M12,-1*MAX($L12,N12),0):OFFSET($M12,0,0))) -> 0.88100381 | E13: =IF(NOT($K12),E12,IFERROR(STDEV(OFFSET($M12,-1*MAX($L12,N12),0):OFFSET($M12,0,0)),E12)) -> 0.1083766 | F13: =MAX(0,D13-3*SQRT(D13*(1-D13)/B13)) -> 0.7967769 | G13: 0.95 | H13: =(C13-D13)/E13 -> -0.30953345 | I13: =IF(P13="y",I12,IF(K12,0,MAX(0,I12+H13-0.5))) -> 0 | J13: =IF(P13="y",J12,IF(K12,0,MAX(0,J12-H13+0.5))) -> 0 | K13: {=IFERROR(OR(ABS(I13)>=4, ABS(J13)>=4),FALSE())} -> FALSE | L13: =IF(K12,0,L12+1) -> 0 | M13: =IF(P13="y","",C13) -> 0.84745763 | N13: =MIN(5,N12+1) -> 5 | O13: =IF(C13>=G13,"Yes","No") -> No
A14: ='Raw-Data'!I30 -> 46195 | B14: ='Raw-Data'!J30 -> 100 | C14: ='Raw-Data'!K30 -> 0.86813187 | D14: =IF(NOT($K13),D13,AVERAGE(OFFSET($M13,-1*MAX($L13,N13),0):OFFSET($M13,0,0))) -> 0.88100381 | E14: =IF(NOT($K13),E13,IFERROR(STDEV(OFFSET($M13,-1*MAX($L13,N13),0):OFFSET($M13,0,0)),E13)) -> 0.1083766 | F14: =MAX(0,D14-3*SQRT(D14*(1-D14)/B14)) -> 0.7838686 | G14: 0.95 | H14: =(C14-D14)/E14 -> -0.11877049 | I14: =IF(P14="y",I13,IF(K13,0,MAX(0,I13+H14-0.5))) -> 0 | J14: =IF(P14="y",J13,IF(K13,0,MAX(0,J13-H14+0.5))) -> 0.61877049 | K14: {=IFERROR(OR(ABS(I14)>=4, ABS(J14)>=4),FALSE())} -> FALSE | L14: =IF(K13,0,L13+1) -> 1 | M14: =IF(P14="y","",C14) -> 0.86813187 | N14: =MIN(5,N13+1) -> 5 | O14: =IF(C14>=G14,"Yes","No") -> No
A15: ='Raw-Data'!I29 -> 46196 | B15: ='Raw-Data'!J29 -> 126 | C15: ='Raw-Data'!K29 -> 0.75961538 | D15: =IF(NOT($K14),D14,AVERAGE(OFFSET($M14,-1*MAX($L14,N14),0):OFFSET($M14,0,0))) -> 0.88100381 | E15: =IF(NOT($K14),E14,IFERROR(STDEV(OFFSET($M14,-1*MAX($L14,N14),0):OFFSET($M14,0,0)),E14)) -> 0.1083766 | F15: =MAX(0,D15-3*SQRT(D15*(1-D15)/B15)) -> 0.79446889 | G15: 0.95 | H15: =(C15-D15)/E15 -> -1.1200612 | I15: =IF(P15="y",I14,IF(K14,0,MAX(0,I14+H15-0.5))) -> 0 | J15: =IF(P15="y",J14,IF(K14,0,MAX(0,J14-H15+0.5))) -> 2.2388317 | K15: {=IFERROR(OR(ABS(I15)>=4, ABS(J15)>=4),FALSE())} -> FALSE | L15: =IF(K14,0,L14+1) -> 2 | M15: =IF(P15="y","",C15) -> 0.75961538 | N15: =MIN(5,N14+1) -> 5 | O15: =IF(C15>=G15,"Yes","No") -> No
A16: ='Raw-Data'!I28 -> 46197 | B16: ='Raw-Data'!J28 -> 105 | C16: ='Raw-Data'!K28 -> 0.78651685 | D16: =IF(NOT($K15),D15,AVERAGE(OFFSET($M15,-1*MAX($L15,N15),0):OFFSET($M15,0,0))) -> 0.88100381 | E16: =IF(NOT($K15),E15,IFERROR(STDEV(OFFSET($M15,-1*MAX($L15,N15),0):OFFSET($M15,0,0)),E15)) -> 0.1083766 | F16: =MAX(0,D16-3*SQRT(D16*(1-D16)/B16)) -> 0.78620955 | G16: 0.95 | H16: =(C16-D16)/E16 -> -0.87183908 | I16: =IF(P16="y",I15,IF(K15,0,MAX(0,I15+H16-0.5))) -> 0 | J16: =IF(P16="y",J15,IF(K15,0,MAX(0,J15-H16+0.5))) -> 3.6106708 | K16: {=IFERROR(OR(ABS(I16)>=4, ABS(J16)>=4),FALSE())} -> FALSE | L16: =IF(K15,0,L15+1) -> 3 | M16: =IF(P16="y","",C16) -> 0.78651685 | N16: =MIN(5,N15+1) -> 5 | O16: =IF(C16>=G16,"Yes","No") -> No
A17: ='Raw-Data'!I27 -> 46198 | B17: ='Raw-Data'!J27 -> 106 | C17: ='Raw-Data'!K27 -> 0.95698925 | D17: =IF(NOT($K16),D16,AVERAGE(OFFSET($M16,-1*MAX($L16,N16),0):OFFSET($M16,0,0))) -> 0.88100381 | E17: =IF(NOT($K16),E16,IFERROR(STDEV(OFFSET($M16,-1*MAX($L16,N16),0):OFFSET($M16,0,0)),E16)) -> 0.1083766 | F17: =MAX(0,D17-3*SQRT(D17*(1-D17)/B17)) -> 0.78665776 | G17: 0.95 | H17: =(C17-D17)/E17 -> 0.70112402 | I17: =IF(P17="y",I16,IF(K16,0,MAX(0,I16+H17-0.5))) -> 0.20112402 | J17: =IF(P17="y",J16,IF(K16,0,MAX(0,J16-H17+0.5))) -> 3.4095468 | K17: {=IFERROR(OR(ABS(I17)>=4, ABS(J17)>=4),FALSE())} -> FALSE | L17: =IF(K16,0,L16+1) -> 4 | M17: =IF(P17="y","",C17) -> 0.95698925 | N17: =MIN(5,N16+1) -> 5 | O17: =IF(C17>=G17,"Yes","No") -> Yes
A18: ='Raw-Data'!I26 -> 46199 | B18: ='Raw-Data'!J26 -> 128 | C18: ='Raw-Data'!K26 -> 0.90291262 | D18: =IF(NOT($K17),D17,AVERAGE(OFFSET($M17,-1*MAX($L17,N17),0):OFFSET($M17,0,0))) -> 0.88100381 | E18: =IF(NOT($K17),E17,IFERROR(STDEV(OFFSET($M17,-1*MAX($L17,N17),0):OFFSET($M17,0,0)),E17)) -> 0.1083766 | F18: =MAX(0,D18-3*SQRT(D18*(1-D18)/B18)) -> 0.7951476 | G18: 0.95 | H18: =(C18-D18)/E18 -> 0.20215444 | I18: =IF(P18="y",I17,IF(K17,0,MAX(0,I17+H18-0.5))) -> 0 | J18: =IF(P18="y",J17,IF(K17,0,MAX(0,J17-H18+0.5))) -> 3.7073923 | K18: {=IFERROR(OR(ABS(I18)>=4, ABS(J18)>=4),FALSE())} -> FALSE | L18: =IF(K17,0,L17+1) -> 5 | M18: =IF(P18="y","",C18) -> 0.90291262 | N18: =MIN(5,N17+1) -> 5 | O18: =IF(C18>=G18,"Yes","No") -> No
A19: ='Raw-Data'!I25 -> 46200 | B19: ='Raw-Data'!J25 -> 122 | C19: ='Raw-Data'!K25 -> 0.84259259 | D19: =IF(NOT($K18),D18,AVERAGE(OFFSET($M18,-1*MAX($L18,N18),0):OFFSET($M18,0,0))) -> 0.88100381 | E19: =IF(NOT($K18),E18,IFERROR(STDEV(OFFSET($M18,-1*MAX($L18,N18),0):OFFSET($M18,0,0)),E18)) -> 0.1083766 | F19: =MAX(0,D19-3*SQRT(D19*(1-D19)/B19)) -> 0.79306172 | G19: 0.95 | H19: =(C19-D19)/E19 -> -0.35442353 | I19: =IF(P19="y",I18,IF(K18,0,MAX(0,I18+H19-0.5))) -> 0 | J19: =IF(P19="y",J18,IF(K18,0,MAX(0,J18-H19+0.5))) -> 4.5618158 | K19: {=IFERROR(OR(ABS(I19)>=4, ABS(J19)>=4),FALSE())} -> TRUE | L19: =IF(K18,0,L18+1) -> 6 | M19: =IF(P19="y","",C19) -> 0.84259259 | N19: =MIN(5,N18+1) -> 5 | O19: =IF(C19>=G19,"Yes","No") -> No
A20: ='Raw-Data'!I24 -> 46201 | B20: ='Raw-Data'!J24 -> 102 | C20: ='Raw-Data'!K24 -> 0.95555556 | D20: =IF(NOT($K19),D19,AVERAGE(OFFSET($M19,-1*MAX($L19,N19),0):OFFSET($M19,0,0))) -> 0.85203089 | E20: =IF(NOT($K19),E19,IFERROR(STDEV(OFFSET($M19,-1*MAX($L19,N19),0):OFFSET($M19,0,0)),E19)) -> 0.066842052 | F20: =MAX(0,D20-3*SQRT(D20*(1-D20)/B20)) -> 0.74655957 | G20: 0.95 | H20: =(C20-D20)/E20 -> 1.5487955 | I20: =IF(P20="y",I19,IF(K19,0,MAX(0,I19+H20-0.5))) -> 0 | J20: =IF(P20="y",J19,IF(K19,0,MAX(0,J19-H20+0.5))) -> 0 | K20: {=IFERROR(OR(ABS(I20)>=4, ABS(J20)>=4),FALSE())} -> FALSE | L20: =IF(K19,0,L19+1) -> 0 | M20: =IF(P20="y","",C20) -> 0.95555556 | N20: =MIN(5,N19+1) -> 5 | O20: =IF(C20>=G20,"Yes","No") -> Yes
A21: ='Raw-Data'!I23 -> 46202 | B21: ='Raw-Data'!J23 -> 107 | C21: ='Raw-Data'!K23 -> 0.96629213 | D21: =IF(NOT($K20),D20,AVERAGE(OFFSET($M20,-1*MAX($L20,N20),0):OFFSET($M20,0,0))) -> 0.85203089 | E21: =IF(NOT($K20),E20,IFERROR(STDEV(OFFSET($M20,-1*MAX($L20,N20),0):OFFSET($M20,0,0)),E20)) -> 0.066842052 | F21: =MAX(0,D21-3*SQRT(D21*(1-D21)/B21)) -> 0.74905333 | G21: 0.95 | H21: =(C21-D21)/E21 -> 1.7094216 | I21: =IF(P21="y",I20,IF(K20,0,MAX(0,I20+H21-0.5))) -> 1.2094216 | J21: =IF(P21="y",J20,IF(K20,0,MAX(0,J20-H21+0.5))) -> 0 | K21: {=IFERROR(OR(ABS(I21)>=4, ABS(J21)>=4),FALSE())} -> FALSE | L21: =IF(K20,0,L20+1) -> 1 | M21: =IF(P21="y","",C21) -> 0.96629213 | N21: =MIN(5,N20+1) -> 5 | O21: =IF(C21>=G21,"Yes","No") -> Yes
A22: ='Raw-Data'!I22 -> 46203 | B22: ='Raw-Data'!J22 -> 93 | C22: ='Raw-Data'!K22 -> 0.85897436 | D22: =IF(NOT($K21),D21,AVERAGE(OFFSET($M21,-1*MAX($L21,N21),0):OFFSET($M21,0,0))) -> 0.85203089 | E22: =IF(NOT($K21),E21,IFERROR(STDEV(OFFSET($M21,-1*MAX($L21,N21),0):OFFSET($M21,0,0)),E21)) -> 0.066842052 | F22: =MAX(0,D22-3*SQRT(D22*(1-D22)/B22)) -> 0.74157395 | G22: 0.95 | H22: =(C22-D22)/E22 -> 0.10387883 | I22: =IF(P22="y",I21,IF(K21,0,MAX(0,I21+H22-0.5))) -> 0.81330046 | J22: =IF(P22="y",J21,IF(K21,0,MAX(0,J21-H22+0.5))) -> 0.39612117 | K22: {=IFERROR(OR(ABS(I22)>=4, ABS(J22)>=4),FALSE())} -> FALSE | L22: =IF(K21,0,L21+1) -> 2 | M22: =IF(P22="y","",C22) -> 0.85897436 | N22: =MIN(5,N21+1) -> 5 | O22: =IF(C22>=G22,"Yes","No") -> No
A23: ='Raw-Data'!I21 -> 46204 | B23: ='Raw-Data'!J21 -> 118 | C23: ='Raw-Data'!K21 -> 0.93 | D23: =IF(NOT($K22),D22,AVERAGE(OFFSET($M22,-1*MAX($L22,N22),0):OFFSET($M22,0,0))) -> 0.85203089 | E23: =IF(NOT($K22),E22,IFERROR(STDEV(OFFSET($M22,-1*MAX($L22,N22),0):OFFSET($M22,0,0)),E22)) -> 0.066842052 | F23: =MAX(0,D23-3*SQRT(D23*(1-D23)/B23)) -> 0.75397053 | G23: 0.95 | H23: =(C23-D23)/E23 -> 1.166468 | I23: =IF(P23="y",I22,IF(K22,0,MAX(0,I22+H23-0.5))) -> 1.4797685 | J23: =IF(P23="y",J22,IF(K22,0,MAX(0,J22-H23+0.5))) -> 0 | K23: {=IFERROR(OR(ABS(I23)>=4, ABS(J23)>=4),FALSE())} -> FALSE | L23: =IF(K22,0,L22+1) -> 3 | M23: =IF(P23="y","",C23) -> 0.93 | N23: =MIN(5,N22+1) -> 5 | O23: =IF(C23>=G23,"Yes","No") -> No
A24: ='Raw-Data'!I20 -> 46205 | B24: ='Raw-Data'!J20 -> 78 | C24: ='Raw-Data'!K20 -> 0.94117647 | D24: =IF(NOT($K23),D23,AVERAGE(OFFSET($M23,-1*MAX($L23,N23),0):OFFSET($M23,0,0))) -> 0.85203089 | E24: =IF(NOT($K23),E23,IFERROR(STDEV(OFFSET($M23,-1*MAX($L23,N23),0):OFFSET($M23,0,0)),E23)) -> 0.066842052 | F24: =MAX(0,D24-3*SQRT(D24*(1-D24)/B24)) -> 0.73141982 | G24: 0.95 | H24: =(C24-D24)/E24 -> 1.3336752 | I24: =IF(P24="y",I23,IF(K23,0,MAX(0,I23+H24-0.5))) -> 2.3134436 | J24: =IF(P24="y",J23,IF(K23,0,MAX(0,J23-H24+0.5))) -> 0 | K24: {=IFERROR(OR(ABS(I24)>=4, ABS(J24)>=4),FALSE())} -> FALSE | L24: =IF(K23,0,L23+1) -> 4 | M24: =IF(P24="y","",C24) -> 0.94117647 | N24: =MIN(5,N23+1) -> 5 | O24: =IF(C24>=G24,"Yes","No") -> No
A25: ='Raw-Data'!I19 -> 46206 | B25: ='Raw-Data'!J19 -> 124 | C25: ='Raw-Data'!K19 -> 0.90654206 | D25: =IF(NOT($K24),D24,AVERAGE(OFFSET($M24,-1*MAX($L24,N24),0):OFFSET($M24,0,0))) -> 0.85203089 | E25: =IF(NOT($K24),E24,IFERROR(STDEV(OFFSET($M24,-1*MAX($L24,N24),0):OFFSET($M24,0,0)),E24)) -> 0.066842052 | F25: =MAX(0,D25-3*SQRT(D25*(1-D25)/B25)) -> 0.75637237 | G25: 0.95 | H25: =(C25-D25)/E25 -> 0.81552211 | I25: =IF(P25="y",I24,IF(K24,0,MAX(0,I24+H25-0.5))) -> 2.6289657 | J25: =IF(P25="y",J24,IF(K24,0,MAX(0,J24-H25+0.5))) -> 0 | K25: {=IFERROR(OR(ABS(I25)>=4, ABS(J25)>=4),FALSE())} -> FALSE | L25: =IF(K24,0,L24+1) -> 5 | M25: =IF(P25="y","",C25) -> 0.90654206 | N25: =MIN(5,N24+1) -> 5 | O25: =IF(C25>=G25,"Yes","No") -> No
A26: ='Raw-Data'!I18 -> 46207 | B26: ='Raw-Data'!J18 -> 129 | C26: ='Raw-Data'!K18 -> 0.90654206 | D26: =IF(NOT($K25),D25,AVERAGE(OFFSET($M25,-1*MAX($L25,N25),0):OFFSET($M25,0,0))) -> 0.85203089 | E26: =IF(NOT($K25),E25,IFERROR(STDEV(OFFSET($M25,-1*MAX($L25,N25),0):OFFSET($M25,0,0)),E25)) -> 0.066842052 | F26: =MAX(0,D26-3*SQRT(D26*(1-D26)/B26)) -> 0.75824454 | G26: 0.95 | H26: =(C26-D26)/E26 -> 0.81552211 | I26: =IF(P26="y",I25,IF(K25,0,MAX(0,I25+H26-0.5))) -> 2.9444878 | J26: =IF(P26="y",J25,IF(K25,0,MAX(0,J25-H26+0.5))) -> 0 | K26: {=IFERROR(OR(ABS(I26)>=4, ABS(J26)>=4),FALSE())} -> FALSE | L26: =IF(K25,0,L25+1) -> 6 | M26: =IF(P26="y","",C26) -> 0.90654206 | N26: =MIN(5,N25+1) -> 5 | O26: =IF(C26>=G26,"Yes","No") -> No
A27: ='Raw-Data'!I17 -> 46208 | B27: ='Raw-Data'!J17 -> 140 | C27: ='Raw-Data'!K17 -> 0.90322581 | D27: =IF(NOT($K26),D26,AVERAGE(OFFSET($M26,-1*MAX($L26,N26),0):OFFSET($M26,0,0))) -> 0.85203089 | E27: =IF(NOT($K26),E26,IFERROR(STDEV(OFFSET($M26,-1*MAX($L26,N26),0):OFFSET($M26,0,0)),E26)) -> 0.066842052 | F27: =MAX(0,D27-3*SQRT(D27*(1-D27)/B27)) -> 0.76200437 | G27: 0.95 | H27: =(C27-D27)/E27 -> 0.76590888 | I27: =IF(P27="y",I26,IF(K26,0,MAX(0,I26+H27-0.5))) -> 3.2103967 | J27: =IF(P27="y",J26,IF(K26,0,MAX(0,J26-H27+0.5))) -> 0 | K27: {=IFERROR(OR(ABS(I27)>=4, ABS(J27)>=4),FALSE())} -> FALSE | L27: =IF(K26,0,L26+1) -> 7 | M27: =IF(P27="y","",C27) -> 0.90322581 | N27: =MIN(5,N26+1) -> 5 | O27: =IF(C27>=G27,"Yes","No") -> No
A28: ='Raw-Data'!I16 -> 46209 | B28: ='Raw-Data'!J16 -> 94 | C28: ='Raw-Data'!K16 -> 0.93421053 | D28: =IF(NOT($K27),D27,AVERAGE(OFFSET($M27,-1*MAX($L27,N27),0):OFFSET($M27,0,0))) -> 0.85203089 | E28: =IF(NOT($K27),E27,IFERROR(STDEV(OFFSET($M27,-1*MAX($L27,N27),0):OFFSET($M27,0,0)),E27)) -> 0.066842052 | F28: =MAX(0,D28-3*SQRT(D28*(1-D28)/B28)) -> 0.74216306 | G28: 0.95 | H28: =(C28-D28)/E28 -> 1.2294602 | I28: =IF(P28="y",I27,IF(K27,0,MAX(0,I27+H28-0.5))) -> 3.9398569 | J28: =IF(P28="y",J27,IF(K27,0,MAX(0,J27-H28+0.5))) -> 0 | K28: {=IFERROR(OR(ABS(I28)>=4, ABS(J28)>=4),FALSE())} -> FALSE | L28: =IF(K27,0,L27+1) -> 8 | M28: =IF(P28="y","",C28) -> 0.93421053 | N28: =MIN(5,N27+1) -> 5 | O28: =IF(C28>=G28,"Yes","No") -> No
A29: ='Raw-Data'!I15 -> 46210 | B29: ='Raw-Data'!J15 -> 115 | C29: ='Raw-Data'!K15 -> 0.89690722 | D29: =IF(NOT($K28),D28,AVERAGE(OFFSET($M28,-1*MAX($L28,N28),0):OFFSET($M28,0,0))) -> 0.85203089 | E29: =IF(NOT($K28),E28,IFERROR(STDEV(OFFSET($M28,-1*MAX($L28,N28),0):OFFSET($M28,0,0)),E28)) -> 0.066842052 | F29: =MAX(0,D29-3*SQRT(D29*(1-D29)/B29)) -> 0.75269972 | G29: 0.95 | H29: =(C29-D29)/E29 -> 0.67137872 | I29: =IF(P29="y",I28,IF(K28,0,MAX(0,I28+H29-0.5))) -> 4.1112356 | J29: =IF(P29="y",J28,IF(K28,0,MAX(0,J28-H29+0.5))) -> 0 | K29: {=IFERROR(OR(ABS(I29)>=4, ABS(J29)>=4),FALSE())} -> TRUE | L29: =IF(K28,0,L28+1) -> 9 | M29: =IF(P29="y","",C29) -> 0.89690722 | N29: =MIN(5,N28+1) -> 5 | O29: =IF(C29>=G29,"Yes","No") -> No
A30: ='Raw-Data'!I14 -> 46211 | B30: ='Raw-Data'!J14 -> 108 | C30: ='Raw-Data'!K14 -> 0.90697674 | D30: =IF(NOT($K29),D29,AVERAGE(OFFSET($M29,-1*MAX($L29,N29),0):OFFSET($M29,0,0))) -> 0.91994262 | E30: =IF(NOT($K29),E29,IFERROR(STDEV(OFFSET($M29,-1*MAX($L29,N29),0):OFFSET($M29,0,0)),E29)) -> 0.031725419 | F30: =MAX(0,D30-3*SQRT(D30*(1-D30)/B30)) -> 0.84160138 | G30: 0.95 | H30: =(C30-D30)/E30 -> -0.40869039 | I30: =IF(P30="y",I29,IF(K29,0,MAX(0,I29+H30-0.5))) -> 0 | J30: =IF(P30="y",J29,IF(K29,0,MAX(0,J29-H30+0.5))) -> 0 | K30: {=IFERROR(OR(ABS(I30)>=4, ABS(J30)>=4),FALSE())} -> FALSE | L30: =IF(K29,0,L29+1) -> 0 | M30: =IF(P30="y","",C30) -> 0.90697674 | N30: =MIN(5,N29+1) -> 5 | O30: =IF(C30>=G30,"Yes","No") -> No
A31: ='Raw-Data'!I13 -> 46212 | B31: ='Raw-Data'!J13 -> 105 | C31: ='Raw-Data'!K13 -> 0.97826087 | D31: =IF(NOT($K30),D30,AVERAGE(OFFSET($M30,-1*MAX($L30,N30),0):OFFSET($M30,0,0))) -> 0.91994262 | E31: =IF(NOT($K30),E30,IFERROR(STDEV(OFFSET($M30,-1*MAX($L30,N30),0):OFFSET($M30,0,0)),E30)) -> 0.031725419 | F31: =MAX(0,D31-3*SQRT(D31*(1-D31)/B31)) -> 0.8404901 | G31: 0.95 | H31: =(C31-D31)/E31 -> 1.8382185 | I31: =IF(P31="y",I30,IF(K30,0,MAX(0,I30+H31-0.5))) -> 1.3382185 | J31: =IF(P31="y",J30,IF(K30,0,MAX(0,J30-H31+0.5))) -> 0 | K31: {=IFERROR(OR(ABS(I31)>=4, ABS(J31)>=4),FALSE())} -> FALSE | L31: =IF(K30,0,L30+1) -> 1 | M31: =IF(P31="y","",C31) -> 0.97826087 | N31: =MIN(5,N30+1) -> 5 | O31: =IF(C31>=G31,"Yes","No") -> Yes
A32: ='Raw-Data'!I12 -> 46213 | B32: ='Raw-Data'!J12 -> 137 | C32: ='Raw-Data'!K12 -> 0.95412844 | D32: =IF(NOT($K31),D31,AVERAGE(OFFSET($M31,-1*MAX($L31,N31),0):OFFSET($M31,0,0))) -> 0.91994262 | E32: =IF(NOT($K31),E31,IFERROR(STDEV(OFFSET($M31,-1*MAX($L31,N31),0):OFFSET($M31,0,0)),E31)) -> 0.031725419 | F32: =MAX(0,D32-3*SQRT(D32*(1-D32)/B32)) -> 0.85038543 | G32: 0.95 | H32: =(C32-D32)/E32 -> 1.0775531 | I32: =IF(P32="y",I31,IF(K31,0,MAX(0,I31+H32-0.5))) -> 1.9157715 | J32: =IF(P32="y",J31,IF(K31,0,MAX(0,J31-H32+0.5))) -> 0 | K32: {=IFERROR(OR(ABS(I32)>=4, ABS(J32)>=4),FALSE())} -> FALSE | L32: =IF(K31,0,L31+1) -> 2 | M32: =IF(P32="y","",C32) -> 0.95412844 | N32: =MIN(5,N31+1) -> 5 | O32: =IF(C32>=G32,"Yes","No") -> Yes
A33: ='Raw-Data'!I11 -> 46214 | B33: ='Raw-Data'!J11 -> 136 | C33: ='Raw-Data'!K11 -> 0.94392523 | D33: =IF(NOT($K32),D32,AVERAGE(OFFSET($M32,-1*MAX($L32,N32),0):OFFSET($M32,0,0))) -> 0.91994262 | E33: =IF(NOT($K32),E32,IFERROR(STDEV(OFFSET($M32,-1*MAX($L32,N32),0):OFFSET($M32,0,0)),E32)) -> 0.031725419 | F33: =MAX(0,D33-3*SQRT(D33*(1-D33)/B33)) -> 0.85013017 | G33: 0.95 | H33: =(C33-D33)/E33 -> 0.75594322 | I33: =IF(P33="y",I32,IF(K32,0,MAX(0,I32+H33-0.5))) -> 2.1717148 | J33: =IF(P33="y",J32,IF(K32,0,MAX(0,J32-H33+0.5))) -> 0 | K33: {=IFERROR(OR(ABS(I33)>=4, ABS(J33)>=4),FALSE())} -> FALSE | L33: =IF(K32,0,L32+1) -> 3 | M33: =IF(P33="y","",C33) -> 0.94392523 | N33: =MIN(5,N32+1) -> 5 | O33: =IF(C33>=G33,"Yes","No") -> No
A34: ='Raw-Data'!I10 -> 46215 | B34: ='Raw-Data'!J10 -> 137 | C34: ='Raw-Data'!K10 -> 0.96330275 | D34: =IF(NOT($K33),D33,AVERAGE(OFFSET($M33,-1*MAX($L33,N33),0):OFFSET($M33,0,0))) -> 0.91994262 | E34: =IF(NOT($K33),E33,IFERROR(STDEV(OFFSET($M33,-1*MAX($L33,N33),0):OFFSET($M33,0,0)),E33)) -> 0.031725419 | F34: =MAX(0,D34-3*SQRT(D34*(1-D34)/B34)) -> 0.85038543 | G34: 0.95 | H34: =(C34-D34)/E34 -> 1.3667316 | I34: =IF(P34="y",I33,IF(K33,0,MAX(0,I33+H34-0.5))) -> 3.0384464 | J34: =IF(P34="y",J33,IF(K33,0,MAX(0,J33-H34+0.5))) -> 0 | K34: {=IFERROR(OR(ABS(I34)>=4, ABS(J34)>=4),FALSE())} -> FALSE | L34: =IF(K33,0,L33+1) -> 4 | M34: =IF(P34="y","",C34) -> 0.96330275 | N34: =MIN(5,N33+1) -> 5 | O34: =IF(C34>=G34,"Yes","No") -> Yes
A35: ='Raw-Data'!I9 -> 46216 | B35: ='Raw-Data'!J9 -> 131 | C35: ='Raw-Data'!K9 -> 0.90178571 | D35: =IF(NOT($K34),D34,AVERAGE(OFFSET($M34,-1*MAX($L34,N34),0):OFFSET($M34,0,0))) -> 0.91994262 | E35: =IF(NOT($K34),E34,IFERROR(STDEV(OFFSET($M34,-1*MAX($L34,N34),0):OFFSET($M34,0,0)),E34)) -> 0.031725419 | F35: =MAX(0,D35-3*SQRT(D35*(1-D35)/B35)) -> 0.84881035 | G35: 0.95 | H35: =(C35-D35)/E35 -> -0.57231408 | I35: =IF(P35="y",I34,IF(K34,0,MAX(0,I34+H35-0.5))) -> 1.9661323 | J35: =IF(P35="y",J34,IF(K34,0,MAX(0,J34-H35+0.5))) -> 1.0723141 | K35: {=IFERROR(OR(ABS(I35)>=4, ABS(J35)>=4),FALSE())} -> FALSE | L35: =IF(K34,0,L34+1) -> 5 | M35: =IF(P35="y","",C35) -> 0.90178571 | N35: =MIN(5,N34+1) -> 5 | O35: =IF(C35>=G35,"Yes","No") -> No
A36: ='Raw-Data'!I8 -> 46217 | B36: ='Raw-Data'!J8 -> 140 | C36: ='Raw-Data'!K8 -> 0.95762712 | D36: =IF(NOT($K35),D35,AVERAGE(OFFSET($M35,-1*MAX($L35,N35),0):OFFSET($M35,0,0))) -> 0.91994262 | E36: =IF(NOT($K35),E35,IFERROR(STDEV(OFFSET($M35,-1*MAX($L35,N35),0):OFFSET($M35,0,0)),E35)) -> 0.031725419 | F36: =MAX(0,D36-3*SQRT(D36*(1-D36)/B36)) -> 0.85113472 | G36: 0.95 | H36: =(C36-D36)/E36 -> 1.187833 | I36: =IF(P36="y",I35,IF(K35,0,MAX(0,I35+H36-0.5))) -> 2.6539654 | J36: =IF(P36="y",J35,IF(K35,0,MAX(0,J35-H36+0.5))) -> 0.38448105 | K36: {=IFERROR(OR(ABS(I36)>=4, ABS(J36)>=4),FALSE())} -> FALSE | L36: =IF(K35,0,L35+1) -> 6 | M36: =IF(P36="y","",C36) -> 0.95762712 | N36: =MIN(5,N35+1) -> 5 | O36: =IF(C36>=G36,"Yes","No") -> Yes
A37: ='Raw-Data'!I7 -> 46218 | B37: ='Raw-Data'!J7 -> 115 | C37: ='Raw-Data'!K7 -> 0.9263 | D37: =IF(NOT($K36),D36,AVERAGE(OFFSET($M36,-1*MAX($L36,N36),0):OFFSET($M36,0,0))) -> 0.91994262 | E37: =IF(NOT($K36),E36,IFERROR(STDEV(OFFSET($M36,-1*MAX($L36,N36),0):OFFSET($M36,0,0)),E36)) -> 0.031725419 | F37: =MAX(0,D37-3*SQRT(D37*(1-D37)/B37)) -> 0.84402311 | G37: 0.95 | H37: =(C37-D37)/E37 -> 0.20038764 | I37: =IF(P37="y",I36,IF(K36,0,MAX(0,I36+H37-0.5))) -> 2.354353 | J37: =IF(P37="y",J36,IF(K36,0,MAX(0,J36-H37+0.5))) -> 0.68409341 | K37: {=IFERROR(OR(ABS(I37)>=4, ABS(J37)>=4),FALSE())} -> FALSE | L37: =IF(K36,0,L36+1) -> 7 | M37: =IF(P37="y","",C37) -> 0.9263 | N37: =MIN(5,N36+1) -> 5 | O37: =IF(C37>=G37,"Yes","No") -> No
A38: ='Raw-Data'!I6 -> 46219 | B38: ='Raw-Data'!J6 -> 136 | C38: ='Raw-Data'!K6 -> 0.9292 | D38: =IF(NOT($K37),D37,AVERAGE(OFFSET($M37,-1*MAX($L37,N37),0):OFFSET($M37,0,0))) -> 0.91994262 | E38: =IF(NOT($K37),E37,IFERROR(STDEV(OFFSET($M37,-1*MAX($L37,N37),0):OFFSET($M37,0,0)),E37)) -> 0.031725419 | F38: =MAX(0,D38-3*SQRT(D38*(1-D38)/B38)) -> 0.85013017 | G38: 0.95 | H38: =(C38-D38)/E38 -> 0.29179699 | I38: =IF(P38="y",I37,IF(K37,0,MAX(0,I37+H38-0.5))) -> 2.14615 | J38: =IF(P38="y",J37,IF(K37,0,MAX(0,J37-H38+0.5))) -> 0.89229641 | K38: {=IFERROR(OR(ABS(I38)>=4, ABS(J38)>=4),FALSE())} -> FALSE | L38: =IF(K37,0,L37+1) -> 8 | M38: =IF(P38="y","",C38) -> 0.9292 | N38: =MIN(5,N37+1) -> 5 | O38: =IF(C38>=G38,"Yes","No") -> No
A41: Analysis & interpretation
A43: Methodology
A44: Tabular CUSUM on HSR hub data (34 days, 13-Jun to 16-Jul). Seed p-bar=90%, target=95%.
...

Sheet HSR Availability
A1: HSR — Instant Availability % — CUSUM Control Chart & Target Analysis
A2: Tabular CUSUM: center line (p-bar) re-estimates once a sustained shift is detected (no UCL). k=0.5 SD allowance, H=4 SD decision interval. S(H)/S(L) floored at zero. Data pulls live from 'Raw-Data' — extend formulas down after adding new rows there.
A4: Date | B4: Sample Size (n) | C4: Availability % | D4: p-bar (CL) | E4: SD | F4: LCL | G4: Target | H4: Z value | I4: S(H) | J4: S(L) | K4: Shift detected? | L4: Count | M4: Consider in calc | N4: Rows | O4: Meets Target? | P4: Ignore? | R4: Summary statistics
A5: ='Raw-Data'!I39 -> 46186 | B5: ='Raw-Data'!J39 -> 125 | C5: ='Raw-Data'!L39 -> 0.8824 | D5: 0.85 | E5: 0.05 | F5: =MAX(0,D5-3*SQRT(D5*(1-D5)/B5)) -> 0.75418768 | G5: 0.9 | H5: =(C5-D5)/E5 -> 0.648 | I5: 0 | J5: 0 | K5: {=IFERROR(OR(ABS(I5)>=4, ABS(J5)>=4),FALSE())} -> FALSE | L5: 0 | M5: =IF(P5="y","",C5) -> 0.8824 | N5: 1 | O5: =IF(C5>=G5,"Yes","No") -> No | R5: Target | S5: 0.9
A6: ='Raw-Data'!I38 -> 46187 | B6: ='Raw-Data'!J38 -> 112 | C6: ='Raw-Data'!L38 -> 0.9783 | D6: =IF(NOT($K5),D5,AVERAGE(OFFSET($M5,-1*MAX($L5,N5),0):OFFSET($M5,0,0))) -> 0.85 | E6: =IF(NOT($K5),E5,IFERROR(STDEV(OFFSET($M5,-1*MAX($L5,N5),0):OFFSET($M5,0,0)),E5)) -> 0.05 | F6: =MAX(0,D6-3*SQRT(D6*(1-D6)/B6)) -> 0.74877977 | G6: 0.9 | H6: =(C6-D6)/E6 -> 2.566 | I6: =IF(P6="y",I5,IF(K5,0,MAX(0,I5+H6-0.5))) -> 2.066 | J6: =IF(P6="y",J5,IF(K5,0,MAX(0,J5-H6+0.5))) -> 0 | K6: {=IFERROR(OR(ABS(I6)>=4, ABS(J6)>=4),FALSE())} -> FALSE | L6: =IF(K5,0,L5+1) -> 1 | M6: =IF(P6="y","",C6) -> 0.9783 | N6: =MIN(5,N5+1) -> 2 | O6: =IF(C6>=G6,"Yes","No") -> Yes | R6: Number of days (k) | S6: 34
A7: ='Raw-Data'!I37 -> 46188 | B7: ='Raw-Data'!J37 -> 101 | C7: ='Raw-Data'!L37 -> 0.44 | D7: =IF(NOT($K6),D6,AVERAGE(OFFSET($M6,-1*MAX($L6,N6),0):OFFSET($M6,0,0))) -> 0.85 | E7: =IF(NOT($K6),E6,IFERROR(STDEV(OFFSET($M6,-1*MAX($L6,N6),0):OFFSET($M6,0,0)),E6)) -> 0.05 | F7: =MAX(0,D7-3*SQRT(D7*(1-D7)/B7)) -> 0.7434102 | G7: 0.9 | H7: =(C7-D7)/E7 -> -8.2 | I7: =IF(P7="y",I6,IF(K6,0,MAX(0,I6+H7-0.5))) -> 0 | J7: =IF(P7="y",J6,IF(K6,0,MAX(0,J6-H7+0.5))) -> 8.7 | K7: {=IFERROR(OR(ABS(I7)>=4, ABS(J7)>=4),FALSE())} -> TRUE | L7: =IF(K6,0,L6+1) -> 2 | M7: =IF(P7="y","",C7) -> 0.44 | N7: =MIN(5,N6+1) -> 3 | O7: =IF(C7>=G7,"Yes","No") -> No | R7: Shifts detected (CUSUM) | S7: =COUNTIF(K5:K38,TRUE()) -> 5
A8: ='Raw-Data'!I36 -> 46189 | B8: ='Raw-Data'!J36 -> 114 | C8: ='Raw-Data'!L36 -> 0.8852 | D8: =IF(NOT($K7),D7,AVERAGE(OFFSET($M7,-1*MAX($L7,N7),0):OFFSET($M7,0,0))) -> 0.7669 | E8: =IF(NOT($K7),E7,IFERROR(STDEV(OFFSET($M7,-1*MAX($L7,N7),0):OFFSET($M7,0,0)),E7)) -> 0.2871357 | F8: =MAX(0,D8-3*SQRT(D8*(1-D8)/B8)) -> 0.64810194 | G8: 0.9 | H8: =(C8-D8)/E8 -> 0.41200032 | I8: =IF(P8="y",I7,IF(K7,0,MAX(0,I7+H8-0.5))) -> 0 | J8: =IF(P8="y",J7,IF(K7,0,MAX(0,J7-H8+0.5))) -> 0 | K8: {=IFERROR(OR(ABS(I8)>=4, ABS(J8)>=4),FALSE())} -> FALSE | L8: =IF(K7,0,L7+1) -> 0 | M8: =IF(P8="y","",C8) -> 0.8852 | N8: =MIN(5,N7+1) -> 4 | O8: =IF(C8>=G8,"Yes","No") -> No | R8: Days meeting target | S8: =COUNTIF(O5:O38,"Yes")&"/"&34 -> 10/34
A9: ='Raw-Data'!I35 -> 46190 | B9: ='Raw-Data'!J35 -> 104 | C9: ='Raw-Data'!L35 -> 0.5584 | D9: =IF(NOT($K8),D8,AVERAGE(OFFSET($M8,-1*MAX($L8,N8),0):OFFSET($M8,0,0))) -> 0.7669 | E9: =IF(NOT($K8),E8,IFERROR(STDEV(OFFSET($M8,-1*MAX($L8,N8),0):OFFSET($M8,0,0)),E8)) -> 0.2871357 | F9: =MAX(0,D9-3*SQRT(D9*(1-D9)/B9)) -> 0.64252156 | G9: 0.9 | H9: =(C9-D9)/E9 -> -0.7261375 | I9: =IF(P9="y",I8,IF(K8,0,MAX(0,I8+H9-0.5))) -> 0 | J9: =IF(P9="y",J8,IF(K8,0,MAX(0,J8-H9+0.5))) -> 1.2261375 | K9: {=IFERROR(OR(ABS(I9)>=4, ABS(J9)>=4),FALSE())} -> FALSE | L9: =IF(K8,0,L8+1) -> 1 | M9: =IF(P9="y","",C9) -> 0.5584 | N9: =MIN(5,N8+1) -> 5 | O9: =IF(C9>=G9,"Yes","No") -> No | R9: Average performance | S9: =AVERAGE(C5:C38) -> 0.77230588
A10: ='Raw-Data'!I34 -> 46191 | B10: ='Raw-Data'!J34 -> 95 | C10: ='Raw-Data'!L34 -> 0.549 | D10: =IF(NOT($K9),D9,AVERAGE(OFFSET($M9,-1*MAX($L9,N9),0):OFFSET($M9,0,0))) -> 0.7669 | E10: =IF(NOT($K9),E9,IFERROR(STDEV(OFFSET($M9,-1*MAX($L9,N9),0):OFFSET($M9,0,0)),E9)) -> 0.2871357 | F10: =MAX(0,D10-3*SQRT(D10*(1-D10)/B10)) -> 0.63676325 | G10: 0.9 | H10: =(C10-D10)/E10 -> -0.75887464 | I10: =IF(P10="y",I9,IF(K9,0,MAX(0,I9+H10-0.5))) -> 0 | J10: =IF(P10="y",J9,IF(K9,0,MAX(0,J9-H10+0.5))) -> 2.4850121 | K10: {=IFERROR(OR(ABS(I10)>=4, ABS(J10)>=4),FALSE())} -> FALSE | L10: =IF(K9,0,L9+1) -> 2 | M10: =IF(P10="y","",C10) -> 0.549 | N10: =MIN(5,N9+1) -> 5 | O10: =IF(C10>=G10,"Yes","No") -> No | R10: Average gap to target | S10: =AVERAGE(C5:C38)-G5 -> -0.12769412
A11: ='Raw-Data'!I33 -> 46192 | B11: ='Raw-Data'!J33 -> 107 | C11: ='Raw-Data'!L33 -> 0.8316 | D11: =IF(NOT($K10),D10,AVERAGE(OFFSET($M10,-1*MAX($L10,N10),0):OFFSET($M10,0,0))) -> 0.7669 | E11: =IF(NOT($K10),E10,IFERROR(STDEV(OFFSET($M10,-1*MAX($L10,N10),0):OFFSET($M10,0,0)),E10)) -> 0.2871357 | F11: =MAX(0,D11-3*SQRT(D11*(1-D11)/B11)) -> 0.64427758 | G11: 0.9 | H11: =(C11-D11)/E11 -> 0.225329 | I11: =IF(P11="y",I10,IF(K10,0,MAX(0,I10+H11-0.5))) -> 0 | J11: =IF(P11="y",J10,IF(K10,0,MAX(0,J10-H11+0.5))) -> 2.7596831 | K11: {=IFERROR(OR(ABS(I11)>=4, ABS(J11)>=4),FALSE())} -> FALSE | L11: =IF(K10,0,L10+1) -> 3 | M11: =IF(P11="y","",C11) -> 0.8316 | N11: =MIN(5,N10+1) -> 5 | O11: =IF(C11>=G11,"Yes","No") -> No | R11: Current phase center (p-bar) | S11: =D38 -> 0.76305
A12: ='Raw-Data'!I32 -> 46193 | B12: ='Raw-Data'!J32 -> 130 | C12: ='Raw-Data'!L32 -> 0.7917 | D12: =IF(NOT($K11),D11,AVERAGE(OFFSET($M11,-1*MAX($L11,N11),0):OFFSET($M11,0,0))) -> 0.7669 | E12: =IF(NOT($K11),E11,IFERROR(STDEV(OFFSET($M11,-1*MAX($L11,N11),0):OFFSET($M11,0,0)),E11)) -> 0.2871357 | F12: =MAX(0,D12-3*SQRT(D12*(1-D12)/B12)) -> 0.65565255 | G12: 0.9 | H12: =(C12-D12)/E12 -> 0.086370312 | I12: =IF(P12="y",I11,IF(K11,0,MAX(0,I11+H12-0.5))) -> 0 | J12: =IF(P12="y",J11,IF(K11,0,MAX(0,J11-H12+0.5))) -> 3.1733128 | K12: {=IFERROR(OR(ABS(I12)>=4, ABS(J12)>=4),FALSE())} -> FALSE | L12: =IF(K11,0,L11+1) -> 4 | M12: =IF(P12="y","",C12) -> 0.7917 | N12: =MIN(5,N11+1) -> 5 | O12: =IF(C12>=G12,"Yes","No") -> No | R12: Current phase LCL | S12: =F38 -> 0.65366528
A13: ='Raw-Data'!I31 -> 46194 | B13: ='Raw-Data'!J31 -> 133 | C13: ='Raw-Data'!L31 -> 0.7126 | D13: =IF(NOT($K12),D12,AVERAGE(OFFSET($M12,-1*MAX($L12,N12),0):OFFSET($M12,0,0))) -> 0.7669 | E13: =IF(NOT($K12),E12,IFERROR(STDEV(OFFSET($M12,-1*MAX($L12,N12),0):OFFSET($M12,0,0)),E12)) -> 0.2871357 | F13: =MAX(0,D13-3*SQRT(D13*(1-D13)/B13)) -> 0.65691437 | G13: 0.9 | H13: =(C13-D13)/E13 -> -0.18910919 | I13: =IF(P13="y",I12,IF(K12,0,MAX(0,I12+H13-0.5))) -> 0 | J13: =IF(P13="y",J12,IF(K12,0,MAX(0,J12-H13+0.5))) -> 3.862422 | K13: {=IFERROR(OR(ABS(I13)>=4, ABS(J13)>=4),FALSE())} -> FALSE | L13: =IF(K12,0,L12+1) -> 5 | M13: =IF(P13="y","",C13) -> 0.7126 | N13: =MIN(5,N12+1) -> 5 | O13: =IF(C13>=G13,"Yes","No") -> No
A14: ='Raw-Data'!I30 -> 46195 | B14: ='Raw-Data'!J30 -> 100 | C14: ='Raw-Data'!L30 -> 0.8171 | D14: =IF(NOT($K13),D13,AVERAGE(OFFSET($M13,-1*MAX($L13,N13),0):OFFSET($M13,0,0))) -> 0.7669 | E14: =IF(NOT($K13),E13,IFERROR(STDEV(OFFSET($M13,-1*MAX($L13,N13),0):OFFSET($M13,0,0)),E13)) -> 0.2871357 | F14: =MAX(0,D14-3*SQRT(D14*(1-D14)/B14)) -> 0.64005839 | G14: 0.9 | H14: =(C14-D14)/E14 -> 0.17483023 | I14: =IF(P14="y",I13,IF(K13,0,MAX(0,I13+H14-0.5))) -> 0 | J14: =IF(P14="y",J13,IF(K13,0,MAX(0,J13-H14+0.5))) -> 4.1875918 | K14: {=IFERROR(OR(ABS(I14)>=4, ABS(J14)>=4),FALSE())} -> TRUE | L14: =IF(K13,0,L13+1) -> 6 | M14: =IF(P14="y","",C14) -> 0.8171 | N14: =MIN(5,N13+1) -> 5 | O14: =IF(C14>=G14,"Yes","No") -> No
A15: ='Raw-Data'!I29 -> 46196 | B15: ='Raw-Data'!J29 -> 126 | C15: ='Raw-Data'!L29 -> 0.3404 | D15: =IF(NOT($K14),D14,AVERAGE(OFFSET($M14,-1*MAX($L14,N14),0):OFFSET($M14,0,0))) -> 0.73508571 | E15: =IF(NOT($K14),E14,IFERROR(STDEV(OFFSET($M14,-1*MAX($L14,N14),0):OFFSET($M14,0,0)),E14)) -> 0.13424615 | F15: =MAX(0,D15-3*SQRT(D15*(1-D15)/B15)) -> 0.61714665 | G15: 0.9 | H15: =(C15-D15)/E15 -> -2.9400152 | I15: =IF(P15="y",I14,IF(K14,0,MAX(0,I14+H15-0.5))) -> 0 | J15: =IF(P15="y",J14,IF(K14,0,MAX(0,J14-H15+0.5))) -> 0 | K15: {=IFERROR(OR(ABS(I15)>=4, ABS(J15)>=4),FALSE())} -> FALSE | L15: =IF(K14,0,L14+1) -> 0 | M15: =IF(P15="y","",C15) -> 0.3404 | N15: =MIN(5,N14+1) -> 5 | O15: =IF(C15>=G15,"Yes","No") -> No
A16: ='Raw-Data'!I28 -> 46197 | B16: ='Raw-Data'!J28 -> 105 | C16: ='Raw-Data'!L28 -> 0.4432 | D16: =IF(NOT($K15),D15,AVERAGE(OFFSET($M15,-1*MAX($L15,N15),0):OFFSET($M15,0,0))) -> 0.73508571 | E16: =IF(NOT($K15),E15,IFERROR(STDEV(OFFSET($M15,-1*MAX($L15,N15),0):OFFSET($M15,0,0)),E15)) -> 0.13424615 | F16: =MAX(0,D16-3*SQRT(D16*(1-D16)/B16)) -> 0.60588995 | G16: 0.9 | H16: =(C16-D16)/E16 -> -2.1742577 | I16: =IF(P16="y",I15,IF(K15,0,MAX(0,I15+H16-0.5))) -> 0 | J16: =IF(P16="y",J15,IF(K15,0,MAX(0,J15-H16+0.5))) -> 2.6742577 | K16: {=IFERROR(OR(ABS(I16)>=4, ABS(J16)>=4),FALSE())} -> FALSE | L16: =IF(K15,0,L15+1) -> 1 | M16: =IF(P16="y","",C16) -> 0.4432 | N16: =MIN(5,N15+1) -> 5 | O16: =IF(C16>=G16,"Yes","No") -> No
A17: ='Raw-Data'!I27 -> 46198 | B17: ='Raw-Data'!J27 -> 106 | C17: ='Raw-Data'!L27 -> 0.6154 | D17: =IF(NOT($K16),D16,AVERAGE(OFFSET($M16,-1*MAX($L16,N16),0):OFFSET($M16,0,0))) -> 0.73508571 | E17: =IF(NOT($K16),E16,IFERROR(STDEV(OFFSET($M16,-1*MAX($L16,N16),0):OFFSET($M16,0,0)),E16)) -> 0.13424615 | F17: =MAX(0,D17-3*SQRT(D17*(1-D17)/B17)) -> 0.60650081 | G17: 0.9 | H17: =(C17-D17)/E17 -> -0.89153929 | I17: =IF(P17="y",I16,IF(K16,0,MAX(0,I16+H17-0.5))) -> 0 | J17: =IF(P17="y",J16,IF(K16,0,MAX(0,J16-H17+0.5))) -> 4.0657969 | K17: {=IFERROR(OR(ABS(I17)>=4, ABS(J17)>=4),FALSE())} -> TRUE | L17: =IF(K16,0,L16+1) -> 2 | M17: =IF(P17="y","",C17) -> 0.6154 | N17: =MIN(5,N16+1) -> 5 | O17: =IF(C17>=G17,"Yes","No") -> No
A18: ='Raw-Data'!I26 -> 46199 | B18: ='Raw-Data'!J26 -> 128 | C18: ='Raw-Data'!L26 -> 0.525 | D18: =IF(NOT($K17),D17,AVERAGE(OFFSET($M17,-1*MAX($L17,N17),0):OFFSET($M17,0,0))) -> 0.62006667 | E18: =IF(NOT($K17),E17,IFERROR(STDEV(OFFSET($M17,-1*MAX($L17,N17),0):OFFSET($M17,0,0)),E17)) -> 0.19305937 | F18: =MAX(0,D18-3*SQRT(D18*(1-D18)/B18)) -> 0.49136352 | G18: 0.9 | H18: =(C18-D18)/E18 -> -0.49242194 | I18: =IF(P18="y",I17,IF(K17,0,MAX(0,I17+H18-0.5))) -> 0 | J18: =IF(P18="y",J17,IF(K17,0,MAX(0,J17-H18+0.5))) -> 0 | K18: {=IFERROR(OR(ABS(I18)>=4, ABS(J18)>=4),FALSE())} -> FALSE | L18: =IF(K17,0,L17+1) -> 0 | M18: =IF(P18="y","",C18) -> 0.525 | N18: =MIN(5,N17+1) -> 5 | O18: =IF(C18>=G18,"Yes","No") -> No
A19: ='Raw-Data'!I25 -> 46200 | B19: ='Raw-Data'!J25 -> 122 | C19: ='Raw-Data'!L25 -> 0.8495 | D19: =IF(NOT($K18),D18,AVERAGE(OFFSET($M18,-1*MAX($L18,N18),0):OFFSET($M18,0,0))) -> 0.62006667 | E19: =IF(NOT($K18),E18,IFERROR(STDEV(OFFSET($M18,-1*MAX($L18,N18),0):OFFSET($M18,0,0)),E18)) -> 0.19305937 | F19: =MAX(0,D19-3*SQRT(D19*(1-D19)/B19)) -> 0.48823667 | G19: 0.9 | H19: =(C19-D19)/E19 -> 1.1884082 | I19: =IF(P19="y",I18,IF(K18,0,MAX(0,I18+H19-0.5))) -> 0.6884082 | J19: =IF(P19="y",J18,IF(K18,0,MAX(0,J18-H19+0.5))) -> 0 | K19: {=IFERROR(OR(ABS(I19)>=4, ABS(J19)>=4),FALSE())} -> FALSE | L19: =IF(K18,0,L18+1) -> 1 | M19: =IF(P19="y","",C19) -> 0.8495 | N19: =MIN(5,N18+1) -> 5 | O19: =IF(C19>=G19,"Yes","No") -> No
A20: ='Raw-Data'!I24 -> 46201 | B20: ='Raw-Data'!J24 -> 102 | C20: ='Raw-Data'!L24 -> 0.9655 | D20: =IF(NOT($K19),D19,AVERAGE(OFFSET($M19,-1*MAX($L19,N19),0):OFFSET($M19,0,0))) -> 0.62006667 | E20: =IF(NOT($K19),E19,IFERROR(STDEV(OFFSET($M19,-1*MAX($L19,N19),0):OFFSET($M19,0,0)),E19)) -> 0.19305937 | F20: =MAX(0,D20-3*SQRT(D20*(1-D20)/B20)) -> 0.47589031 | G20: 0.9 | H20: =(C20-D20)/E20 -> 1.7892597 | I20: =IF(P20="y",I19,IF(K19,0,MAX(0,I19+H20-0.5))) -> 1.9776679 | J20: =IF(P20="y",J19,IF(K19,0,MAX(0,J19-H20+0.5))) -> 0 | K20: {=IFERROR(OR(ABS(I20)>=4, ABS(J20)>=4),FALSE())} -> FALSE | L20: =IF(K19,0,L19+1) -> 2 | M20: =IF(P20="y","",C20) -> 0.9655 | N20: =MIN(5,N19+1) -> 5 | O20: =IF(C20>=G20,"Yes","No") -> Yes
A21: ='Raw-Data'!I23 -> 46202 | B21: ='Raw-Data'!J23 -> 107 | C21: ='Raw-Data'!L23 -> 0.8218 | D21: =IF(NOT($K20),D20,AVERAGE(OFFSET($M20,-1*MAX($L20,N20),0):OFFSET($M20,0,0))) -> 0.62006667 | E21: =IF(NOT($K20),E20,IFERROR(STDEV(OFFSET($M20,-1*MAX($L20,N20),0):OFFSET($M20,0,0)),E20)) -> 0.19305937 | F21: =MAX(0,D21-3*SQRT(D21*(1-D21)/B21)) -> 0.47929921 | G21: 0.9 | H21: =(C21-D21)/E21 -> 1.044929 | I21: =IF(P21="y",I20,IF(K20,0,MAX(0,I20+H21-0.5))) -> 2.5225969 | J21: =IF(P21="y",J20,IF(K20,0,MAX(0,J20-H21+0.5))) -> 0 | K21: {=IFERROR(OR(ABS(I21)>=4, ABS(J21)>=4),FALSE())} -> FALSE | L21: =IF(K20,0,L20+1) -> 3 | M21: =IF(P21="y","",C21) -> 0.8218 | N21: =MIN(5,N20+1) -> 5 | O21: =IF(C21>=G21,"Yes","No") -> No
A22: ='Raw-Data'!I22 -> 46203 | B22: ='Raw-Data'!J22 -> 93 | C22: ='Raw-Data'!L22 -> 0.9306 | D22: =IF(NOT($K21),D21,AVERAGE(OFFSET($M21,-1*MAX($L21,N21),0):OFFSET($M21,0,0))) -> 0.62006667 | E22: =IF(NOT($K21),E21,IFERROR(STDEV(OFFSET($M21,-1*MAX($L21,N21),0):OFFSET($M21,0,0)),E21)) -> 0.19305937 | F22: =MAX(0,D22-3*SQRT(D22*(1-D22)/B22)) -> 0.46907511 | G22: 0.9 | H22: =(C22-D22)/E22 -> 1.6084862 | I22: =IF(P22="y",I21,IF(K21,0,MAX(0,I21+H22-0.5))) -> 3.6310831 | J22: =IF(P22="y",J21,IF(K21,0,MAX(0,J21-H22+0.5))) -> 0 | K22: {=IFERROR(OR(ABS(I22)>=4, ABS(J22)>=4),FALSE())} -> FALSE | L22: =IF(K21,0,L21+1) -> 4 | M22: =IF(P22="y","",C22) -> 0.9306 | N22: =MIN(5,N21+1) -> 5 | O22: =IF(C22>=G22,"Yes","No") -> Yes
A23: ='Raw-Data'!I21 -> 46204 | B23: ='Raw-Data'!J21 -> 118 | C23: ='Raw-Data'!L21 -> 0.7722 | D23: =IF(NOT($K22),D22,AVERAGE(OFFSET($M22,-1*MAX($L22,N22),0):OFFSET($M22,0,0))) -> 0.62006667 | E23: =IF(NOT($K22),E22,IFERROR(STDEV(OFFSET($M22,-1*MAX($L22,N22),0):OFFSET($M22,0,0)),E22)) -> 0.19305937 | F23: =MAX(0,D23-3*SQRT(D23*(1-D23)/B23)) -> 0.48602089 | G23: 0.9 | H23: =(C23-D23)/E23 -> 0.78801322 | I23: =IF(P23="y",I22,IF(K22,0,MAX(0,I22+H23-0.5))) -> 3.9190963 | J23: =IF(P23="y",J22,IF(K22,0,MAX(0,J22-H23+0.5))) -> 0 | K23: {=IFERROR(OR(ABS(I23)>=4, ABS(J23)>=4),FALSE())} -> FALSE | L23: =IF(K22,0,L22+1) -> 5 | M23: =IF(P23="y","",C23) -> 0.7722 | N23: =MIN(5,N22+1) -> 5 | O23: =IF(C23>=G23,"Yes","No") -> No
A24: ='Raw-Data'!I20 -> 46205 | B24: ='Raw-Data'!J20 -> 78 | C24: ='Raw-Data'!L20 -> 0.9278 | D24: =IF(NOT($K23),D23,AVERAGE(OFFSET($M23,-1*MAX($L23,N23),0):OFFSET($M23,0,0))) -> 0.62006667 | E24: =IF(NOT($K23),E23,IFERROR(STDEV(OFFSET($M23,-1*MAX($L23,N23),0):OFFSET($M23,0,0)),E23)) -> 0.19305937 | F24: =MAX(0,D24-3*SQRT(D24*(1-D24)/B24)) -> 0.45519469 | G24: 0.9 | H24: =(C24-D24)/E24 -> 1.5939829 | I24: =IF(P24="y",I23,IF(K23,0,MAX(0,I23+H24-0.5))) -> 5.0130793 | J24: =IF(P24="y",J23,IF(K23,0,MAX(0,J23-H24+0.5))) -> 0 | K24: {=IFERROR(OR(ABS(I24)>=4, ABS(J24)>=4),FALSE())} -> TRUE | L24: =IF(K23,0,L23+1) -> 6 | M24: =IF(P24="y","",C24) -> 0.9278 | N24: =MIN(5,N23+1) -> 5 | O24: =IF(C24>=G24,"Yes","No") -> Yes
A25: ='Raw-Data'!I19 -> 46206 | B25: ='Raw-Data'!J19 -> 124 | C25: ='Raw-Data'!L19 -> 0.7982 | D25: =IF(NOT($K24),D24,AVERAGE(OFFSET($M24,-1*MAX($L24,N24),0):OFFSET($M24,0,0))) -> 0.82748571 | E25: =IF(NOT($K24),E24,IFERROR(STDEV(OFFSET($M24,-1*MAX($L24,N24),0):OFFSET($M24,0,0)),E24)) -> 0.14989692 | F25: =MAX(0,D25-3*SQRT(D25*(1-D25)/B25)) -> 0.72569616 | G25: 0.9 | H25: =(C25-D25)/E25 -> -0.19537235 | I25: =IF(P25="y",I24,IF(K24,0,MAX(0,I24+H25-0.5))) -> 0 | J25: =IF(P25="y",J24,IF(K24,0,MAX(0,J24-H25+0.5))) -> 0 | K25: {=IFERROR(OR(ABS(I25)>=4, ABS(J25)>=4),FALSE())} -> FALSE | L25: =IF(K24,0,L24+1) -> 0 | M25: =IF(P25="y","",C25) -> 0.7982 | N25: =MIN(5,N24+1) -> 5 | O25: =IF(C25>=G25,"Yes","No") -> No
A26: ='Raw-Data'!I18 -> 46207 | B26: ='Raw-Data'!J18 -> 129 | C26: ='Raw-Data'!L18 -> 0.5658 | D26: =IF(NOT($K25),D25,AVERAGE(OFFSET($M25,-1*MAX($L25,N25),0):OFFSET($M25,0,0))) -> 0.82748571 | E26: =IF(NOT($K25),E25,IFERROR(STDEV(OFFSET($M25,-1*MAX($L25,N25),0):OFFSET($M25,0,0)),E25)) -> 0.14989692 | F26: =MAX(0,D26-3*SQRT(D26*(1-D26)/B26)) -> 0.72768832 | G26: 0.9 | H26: =(C26-D26)/E26 -> -1.7457711 | I26: =IF(P26="y",I25,IF(K25,0,MAX(0,I25+H26-0.5))) -> 0 | J26: =IF(P26="y",J25,IF(K25,0,MAX(0,J25-H26+0.5))) -> 2.2457711 | K26: {=IFERROR(OR(ABS(I26)>=4, ABS(J26)>=4),FALSE())} -> FALSE | L26: =IF(K25,0,L25+1) -> 1 | M26: =IF(P26="y","",C26) -> 0.5658 | N26: =MIN(5,N25+1) -> 5 | O26: =IF(C26>=G26,"Yes","No") -> No
A27: ='Raw-Data'!I17 -> 46208 | B27: ='Raw-Data'!J17 -> 140 | C27: ='Raw-Data'!L17 -> 0.5837 | D27: =IF(NOT($K26),D26,AVERAGE(OFFSET($M26,-1*MAX($L26,N26),0):OFFSET($M26,0,0))) -> 0.82748571 | E27: =IF(NOT($K26),E26,IFERROR(STDEV(OFFSET($M26,-1*MAX($L26,N26),0):OFFSET($M26,0,0)),E26)) -> 0.14989692 | F27: =MAX(0,D27-3*SQRT(D27*(1-D27)/B27)) -> 0.73168913 | G27: 0.9 | H27: =(C27-D27)/E27 -> -1.6263557 | I27: =IF(P27="y",I26,IF(K26,0,MAX(0,I26+H27-0.5))) -> 0 | J27: =IF(P27="y",J26,IF(K26,0,MAX(0,J26-H27+0.5))) -> 4.3721267 | K27: {=IFERROR(OR(ABS(I27)>=4, ABS(J27)>=4),FALSE())} -> TRUE | L27: =IF(K26,0,L26+1) -> 2 | M27: =IF(P27="y","",C27) -> 0.5837 | N27: =MIN(5,N26+1) -> 5 | O27: =IF(C27>=G27,"Yes","No") -> No
A28: ='Raw-Data'!I16 -> 46209 | B28: ='Raw-Data'!J16 -> 94 | C28: ='Raw-Data'!L16 -> 0.9799 | D28: =IF(NOT($K27),D27,AVERAGE(OFFSET($M27,-1*MAX($L27,N27),0):OFFSET($M27,0,0))) -> 0.76305 | E28: =IF(NOT($K27),E27,IFERROR(STDEV(OFFSET($M27,-1*MAX($L27,N27),0):OFFSET($M27,0,0)),E27)) -> 0.15975531 | F28: =MAX(0,D28-3*SQRT(D28*(1-D28)/B28)) -> 0.63147839 | G28: 0.9 | H28: =(C28-D28)/E28 -> 1.3573884 | I28: =IF(P28="y",I27,IF(K27,0,MAX(0,I27+H28-0.5))) -> 0 | J28: =IF(P28="y",J27,IF(K27,0,MAX(0,J27-H28+0.5))) -> 0 | K28: {=IFERROR(OR(ABS(I28)>=4, ABS(J28)>=4),FALSE())} -> FALSE | L28: =IF(K27,0,L27+1) -> 0 | M28: =IF(P28="y","",C28) -> 0.9799 | N28: =MIN(5,N27+1) -> 5 | O28: =IF(C28>=G28,"Yes","No") -> Yes
A29: ='Raw-Data'!I15 -> 46210 | B29: ='Raw-Data'!J15 -> 115 | C29: ='Raw-Data'!L15 -> 0.8811 | D29: =IF(NOT($K28),D28,AVERAGE(OFFSET($M28,-1*MAX($L28,N28),0):OFFSET($M28,0,0))) -> 0.76305 | E29: =IF(NOT($K28),E28,IFERROR(STDEV(OFFSET($M28,-1*MAX($L28,N28),0):OFFSET($M28,0,0)),E28)) -> 0.15975531 | F29: =MAX(0,D29-3*SQRT(D29*(1-D29)/B29)) -> 0.64409651 | G29: 0.9 | H29: =(C29-D29)/E29 -> 0.73894258 | I29: =IF(P29="y",I28,IF(K28,0,MAX(0,I28+H29-0.5))) -> 0.23894258 | J29: =IF(P29="y",J28,IF(K28,0,MAX(0,J28-H29+0.5))) -> 0 | K29: {=IFERROR(OR(ABS(I29)>=4, ABS(J29)>=4),FALSE())} -> FALSE | L29: =IF(K28,0,L28+1) -> 1 | M29: =IF(P29="y","",C29) -> 0.8811 | N29: =MIN(5,N28+1) -> 5 | O29: =IF(C29>=G29,"Yes","No") -> No
A30: ='Raw-Data'!I14 -> 46211 | B30: ='Raw-Data'!J14 -> 108 | C30: ='Raw-Data'!L14 -> 0.8316 | D30: =IF(NOT($K29),D29,AVERAGE(OFFSET($M29,-1*MAX($L29,N29),0):OFFSET($M29,0,0))) -> 0.76305 | E30: =IF(NOT($K29),E29,IFERROR(STDEV(OFFSET($M29,-1*MAX($L29,N29),0):OFFSET($M29,0,0)),E29)) -> 0.15975531 | F30: =MAX(0,D30-3*SQRT(D30*(1-D30)/B30)) -> 0.64030205 | G30: 0.9 | H30: =(C30-D30)/E30 -> 0.42909372 | I30: =IF(P30="y",I29,IF(K29,0,MAX(0,I29+H30-0.5))) -> 0.16803629 | J30: =IF(P30="y",J29,IF(K29,0,MAX(0,J29-H30+0.5))) -> 0.070906281 | K30: {=IFERROR(OR(ABS(I30)>=4, ABS(J30)>=4),FALSE())} -> FALSE | L30: =IF(K29,0,L29+1) -> 2 | M30: =IF(P30="y","",C30) -> 0.8316 | N30: =MIN(5,N29+1) -> 5 | O30: =IF(C30>=G30,"Yes","No") -> No
A31: ='Raw-Data'!I13 -> 46212 | B31: ='Raw-Data'!J13 -> 105 | C31: ='Raw-Data'!L13 -> 0.9447 | D31: =IF(NOT($K30),D30,AVERAGE(OFFSET($M30,-1*MAX($L30,N30),0):OFFSET($M30,0,0))) -> 0.76305 | E31: =IF(NOT($K30),E30,IFERROR(STDEV(OFFSET($M30,-1*MAX($L30,N30),0):OFFSET($M30,0,0)),E30)) -> 0.15975531 | F31: =MAX(0,D31-3*SQRT(D31*(1-D31)/B31)) -> 0.63856086 | G31: 0.9 | H31: =(C31-D31)/E31 -> 1.1370514 | I31: =IF(P31="y",I30,IF(K30,0,MAX(0,I30+H31-0.5))) -> 0.8050877 | J31: =IF(P31="y",J30,IF(K30,0,MAX(0,J30-H31+0.5))) -> 0 | K31: {=IFERROR(OR(ABS(I31)>=4, ABS(J31)>=4),FALSE())} -> FALSE | L31: =IF(K30,0,L30+1) -> 3 | M31: =IF(P31="y","",C31) -> 0.9447 | N31: =MIN(5,N30+1) -> 5 | O31: =IF(C31>=G31,"Yes","No") -> Yes
A32: ='Raw-Data'!I12 -> 46213 | B32: ='Raw-Data'!J12 -> 137 | C32: ='Raw-Data'!L12 -> 0.9924 | D32: =IF(NOT($K31),D31,AVERAGE(OFFSET($M31,-1*MAX($L31,N31),0):OFFSET($M31,0,0))) -> 0.76305 | E32: =IF(NOT($K31),E31,IFERROR(STDEV(OFFSET($M31,-1*MAX($L31,N31),0):OFFSET($M31,0,0)),E31)) -> 0.15975531 | F32: =MAX(0,D32-3*SQRT(D32*(1-D32)/B32)) -> 0.65406523 | G32: 0.9 | H32: =(C32-D32)/E32 -> 1.435633 | I32: =IF(P32="y",I31,IF(K31,0,MAX(0,I31+H32-0.5))) -> 1.7407207 | J32: =IF(P32="y",J31,IF(K31,0,MAX(0,J31-H32+0.5))) -> 0 | K32: {=IFERROR(OR(ABS(I32)>=4, ABS(J32)>=4),FALSE())} -> FALSE | L32: =IF(K31,0,L31+1) -> 4 | M32: =IF(P32="y","",C32) -> 0.9924 | N32: =MIN(5,N31+1) -> 5 | O32: =IF(C32>=G32,"Yes","No") -> Yes
A33: ='Raw-Data'!I11 -> 46214 | B33: ='Raw-Data'!J11 -> 136 | C33: ='Raw-Data'!L11 -> 1 | D33: =IF(NOT($K32),D32,AVERAGE(OFFSET($M32,-1*MAX($L32,N32),0):OFFSET($M32,0,0))) -> 0.76305 | E33: =IF(NOT($K32),E32,IFERROR(STDEV(OFFSET($M32,-1*MAX($L32,N32),0):OFFSET($M32,0,0)),E32)) -> 0.15975531 | F33: =MAX(0,D33-3*SQRT(D33*(1-D33)/B33)) -> 0.65366528 | G33: 0.9 | H33: =(C33-D33)/E33 -> 1.4832058 | I33: =IF(P33="y",I32,IF(K32,0,MAX(0,I32+H33-0.5))) -> 2.7239265 | J33: =IF(P33="y",J32,IF(K32,0,MAX(0,J32-H33+0.5))) -> 0 | K33: {=IFERROR(OR(ABS(I33)>=4, ABS(J33)>=4),FALSE())} -> FALSE | L33: =IF(K32,0,L32+1) -> 5 | M33: =IF(P33="y","",C33) -> 1 | N33: =MIN(5,N32+1) -> 5 | O33: =IF(C33>=G33,"Yes","No") -> Yes
A34: ='Raw-Data'!I10 -> 46215 | B34: ='Raw-Data'!J10 -> 137 | C34: ='Raw-Data'!L10 -> 0.8261 | D34: =IF(NOT($K33),D33,AVERAGE(OFFSET($M33,-1*MAX($L33,N33),0):OFFSET($M33,0,0))) -> 0.76305 | E34: =IF(NOT($K33),E33,IFERROR(STDEV(OFFSET($M33,-1*MAX($L33,N33),0):OFFSET($M33,0,0)),E33)) -> 0.15975531 | F34: =MAX(0,D34-3*SQRT(D34*(1-D34)/B34)) -> 0.65406523 | G34: 0.9 | H34: =(C34-D34)/E34 -> 0.39466607 | I34: =IF(P34="y",I33,IF(K33,0,MAX(0,I33+H34-0.5))) -> 2.6185926 | J34: =IF(P34="y",J33,IF(K33,0,MAX(0,J33-H34+0.5))) -> 0.10533393 | K34: {=IFERROR(OR(ABS(I34)>=4, ABS(J34)>=4),FALSE())} -> FALSE | L34: =IF(K33,0,L33+1) -> 6 | M34: =IF(P34="y","",C34) -> 0.8261 | N34: =MIN(5,N33+1) -> 5 | O34: =IF(C34>=G34,"Yes","No") -> No
A35: ='Raw-Data'!I9 -> 46216 | B35: ='Raw-Data'!J9 -> 131 | C35: ='Raw-Data'!L9 -> 0.58 | D35: =IF(NOT($K34),D34,AVERAGE(OFFSET($M34,-1*MAX($L34,N34),0):OFFSET($M34,0,0))) -> 0.76305 | E35: =IF(NOT($K34),E34,IFERROR(STDEV(OFFSET($M34,-1*MAX($L34,N34),0):OFFSET($M34,0,0)),E34)) -> 0.15975531 | F35: =MAX(0,D35-3*SQRT(D35*(1-D35)/B35)) -> 0.65159733 | G35: 0.9 | H35: =(C35-D35)/E35 -> -1.1458148 | I35: =IF(P35="y",I34,IF(K34,0,MAX(0,I34+H35-0.5))) -> 0.97277778 | J35: =IF(P35="y",J34,IF(K34,0,MAX(0,J34-H35+0.5))) -> 1.7511487 | K35: {=IFERROR(OR(ABS(I35)>=4, ABS(J35)>=4),FALSE())} -> FALSE | L35: =IF(K34,0,L34+1) -> 7 | M35: =IF(P35="y","",C35) -> 0.58 | N35: =MIN(5,N34+1) -> 5 | O35: =IF(C35>=G35,"Yes","No") -> No
A36: ='Raw-Data'!I8 -> 46217 | B36: ='Raw-Data'!J8 -> 140 | C36: ='Raw-Data'!L8 -> 0.99 | D36: =IF(NOT($K35),D35,AVERAGE(OFFSET($M35,-1*MAX($L35,N35),0):OFFSET($M35,0,0))) -> 0.76305 | E36: =IF(NOT($K35),E35,IFERROR(STDEV(OFFSET($M35,-1*MAX($L35,N35),0):OFFSET($M35,0,0)),E35)) -> 0.15975531 | F36: =MAX(0,D36-3*SQRT(D36*(1-D36)/B36)) -> 0.65523924 | G36: 0.9 | H36: =(C36-D36)/E36 -> 1.4206101 | I36: =IF(P36="y",I35,IF(K35,0,MAX(0,I35+H36-0.5))) -> 1.8933878 | J36: =IF(P36="y",J35,IF(K35,0,MAX(0,J35-H36+0.5))) -> 0.83053868 | K36: {=IFERROR(OR(ABS(I36)>=4, ABS(J36)>=4),FALSE())} -> FALSE | L36: =IF(K35,0,L35+1) -> 8 | M36: =IF(P36="y","",C36) -> 0.99 | N36: =MIN(5,N35+1) -> 5 | O36: =IF(C36>=G36,"Yes","No") -> Yes
A37: ='Raw-Data'!I7 -> 46218 | B37: ='Raw-Data'!J7 -> 115 | C37: ='Raw-Data'!L7 -> 0.9502 | D37: =IF(NOT($K36),D36,AVERAGE(OFFSET($M36,-1*MAX($L36,N36),0):OFFSET($M36,0,0))) -> 0.76305 | E37: =IF(NOT($K36),E36,IFERROR(STDEV(OFFSET($M36,-1*MAX($L36,N36),0):OFFSET($M36,0,0)),E36)) -> 0.15975531 | F37: =MAX(0,D37-3*SQRT(D37*(1-D37)/B37)) -> 0.64409651 | G37: 0.9 | H37: =(C37-D37)/E37 -> 1.1714791 | I37: =IF(P37="y",I36,IF(K36,0,MAX(0,I36+H37-0.5))) -> 2.5648669 | J37: =IF(P37="y",J36,IF(K36,0,MAX(0,J36-H37+0.5))) -> 0.15905962 | K37: {=IFERROR(OR(ABS(I37)>=4, ABS(J37)>=4),FALSE())} -> FALSE | L37: =IF(K36,0,L36+1) -> 9 | M37: =IF(P37="y","",C37) -> 0.9502 | N37: =MIN(5,N36+1) -> 5 | O37: =IF(C37>=G37,"Yes","No") -> Yes
A38: ='Raw-Data'!I6 -> 46219 | B38: ='Raw-Data'!J6 -> 136 | C38: ='Raw-Data'!L6 -> 0.697 | D38: =IF(NOT($K37),D37,AVERAGE(OFFSET($M37,-1*MAX($L37,N37),0):OFFSET($M37,0,0))) -> 0.76305 | E38: =IF(NOT($K37),E37,IFERROR(STDEV(OFFSET($M37,-1*MAX($L37,N37),0):OFFSET($M37,0,0)),E37)) -> 0.15975531 | F38: =MAX(0,D38-3*SQRT(D38*(1-D38)/B38)) -> 0.65366528 | G38: 0.9 | H38: =(C38-D38)/E38 -> -0.41344479 | I38: =IF(P38="y",I37,IF(K37,0,MAX(0,I37+H38-0.5))) -> 1.6514221 | J38: =IF(P38="y",J37,IF(K37,0,MAX(0,J37-H38+0.5))) -> 1.0725044 | K38: {=IFERROR(OR(ABS(I38)>=4, ABS(J38)>=4),FALSE())} -> FALSE | L38: =IF(K37,0,L37+1) -> 10 | M38: =IF(P38="y","",C38) -> 0.697 | N38: =MIN(5,N37+1) -> 5 | O38: =IF(C38>=G38,"Yes","No") -> No
A41: Analysis & interpretation
A43: Methodology
A44: Tabular CUSUM on HSR hub data. Seed p-bar=85%, target=90%.
...

Sheet Central Arrival OT
